Workbook
Name SegmentaciónDeDatos_STATUS_FINAL: #N/A

Sheet Hoja2

Sheet PLANEAMIENTO
L2: CILINDRO | U2: VASTAGO | AD2: TAPA | AG2: PISTON | AJ2: FIN | AL2: TAPA CI | AO2: CUERPO INT.
L3: ESTANDAR | P3: FABRICACION | U3: ESTANDAR | X3: FABRICACION | AD3: ESTANDAR | AF3: N | AG3: ESTANDAR | AI3: N | AL3: ESTANDAR | AO3: ESTANDAR
A4: HP&K | B4: MINA | C4: DESCRIPCION | D4: MODELO | E4: FECHA ESTIMADA DE TERMINO DE REPARACION | F4: ESTIMADO | G4: Nombre | H4: Fecha de armado | I4: STATUS FINAL | J4: RQ | K4: FECHA | L4: Relleno | M4: Barrenado | N4: Bruñido | O4: Soldadura (Dados) | P4: Corte | Q4: Encastre | R4: Diam Salida. | S4: Soldadura | T4: Bocinas / Dados | U4: Relleno2 | V4: Barrenado3 | W4: Cromado | X4: Corte4 | Y4: Encastre5 | Z4: Espiga | AA4: Soldadura2 | AB4: Maquinar soldadura | AC4: Bocinas2 | AD4: Pulido | AE4: Rectificado | AF4: Fabricacion | AG4: Pulido2 | AH4: Rectificado2 | AI4: Fabricación | AJ4: ARMADO | AK4: PINTURA | AL4: Pulido3 / Releno | AM4: Rectificado3 / Barrenado | AN4: Fabricacion2 | AO4: Bruñido2 | AP4: Cromado4 | AQ4: Bruñido3 | AR4: Cromado2 | AS4: Cromado3 | AT4: AVANCE | AU4: FECHA ESTIMADA DE TERMINO DE REPARACION2
A5: 254824 | B5: UNIMAQ | C5: CILINDRO DE GATA ESTABILIZADORA | D5: 1219 | I5: LISTO PARA DESPACHO | AT5: =IFERROR((COUNTIF(Tabla1[[#This Row],[Relleno]:[Cromado3]],"OK")*1+COUNTIF(Tabla1[[#This Row],[Relleno]:[Cromado3]],"PR")*0.5+COUNTIF(Tabla1[[#This Row],[Relleno]:[Cromado3]],"TS")*0.05)/(COUNTIF(Tabla1[[#This Row],[Relleno]:[Cromado3]],"OK")+COUNTIF(Tabla1[[#This Row],[Relleno]:[Cromado3]],"PR")+COUNTIF(Tabla1[[#This Row],[Relleno]:[Cromado3]],"TS")+COUNTIF(Tabla1[[#This Row],[Relleno]:[Cromado3]],"X")),0) -> 0
A6: 254924 | B6: UNIMAQ | C6: CILINDRO DE GATA ESTABILIZADORA | D6: 1219 | I6: LISTO PARA DESPACHO | AT6: =IFERROR((COUNTIF(Tabla1[[#This Row],[Relleno]:[Cromado3]],"OK")*1+COUNTIF(Tabla1[[#This Row],[Relleno]:[Cromado3]],"PR")*0.5+COUNTIF(Tabla1[[#This Row],[Relleno]:[Cromado3]],"TS")*0.05)/(COUNTIF(Tabla1[[#This Row],[Relleno]:[Cromado3]],"OK")+COUNTIF(Tabla1[[#This Row],[Relleno]:[Cromado3]],"PR")+COUNTIF(Tabla1[[#This Row],[Relleno]:[Cromado3]],"TS")+COUNTIF(Tabla1[[#This Row],[Relleno]:[Cromado3]],"X")),0) -> 0
A7: 255024 | B7: UNIMAQ | C7: CILINDRO DE GATA ESTABILIZADORA | D7: 1219 | I7: LISTO PARA DESPACHO | AT7: =IFERROR((COUNTIF(Tabla1[[#This Row],[Relleno]:[Cromado3]],"OK")*1+COUNTIF(Tabla1[[#This Row],[Relleno]:[Cromado3]],"PR")*0.5+COUNTIF(Tabla1[[#This Row],[Relleno]:[Cromado3]],"TS")*0.05)/(COUNTIF(Tabla1[[#This Row],[Relleno]:[Cromado3]],"OK")+COUNTIF(Tabla1[[#This Row],[Relleno]:[Cromado3]],"PR")+COUNTIF(Tabla1[[#This Row],[Relleno]:[Cromado3]],"TS")+COUNTIF(Tabla1[[#This Row],[Relleno]:[Cromado3]],"X")),0) -> 0
A8: 255124 | B8: UNIMAQ | C8: CILINDRO DE GATA ESTABILIZADORA | D8: 1219 | I8: LISTO PARA DESPACHO | AT8: =IFERROR((COUNTIF(Tabla1[[#This Row],[Relleno]:[Cromado3]],"OK")*1+COUNTIF(Tabla1[[#This Row],[Relleno]:[Cromado3]],"PR")*0.5+COUNTIF(Tabla1[[#This Row],[Relleno]:[Cromado3]],"TS")*0.05)/(COUNTIF(Tabla1[[#This Row],[Relleno]:[Cromado3]],"OK")+COUNTIF(Tabla1[[#This Row],[Relleno]:[Cromado3]],"PR")+COUNTIF(Tabla1[[#This Row],[Relleno]:[Cromado3]],"TS")+COUNTIF(Tabla1[[#This Row],[Relleno]:[Cromado3]],"X")),0) -> 0
A9: 255824 | B9: PERU RAIL | C9: CIGÜEÑAL DE LOCOMOTARA | D9: DL-535 | I9: LISTO PARA DESPACHO | AT9: =IFERROR((COUNTIF(Tabla1[[#This Row],[Relleno]:[Cromado3]],"OK")*1+COUNTIF(Tabla1[[#This Row],[Relleno]:[Cromado3]],"PR")*0.5+COUNTIF(Tabla1[[#This Row],[Relleno]:[Cromado3]],"TS")*0.05)/(COUNTIF(Tabla1[[#This Row],[Relleno]:[Cromado3]],"OK")+COUNTIF(Tabla1[[#This Row],[Relleno]:[Cromado3]],"PR")+COUNTIF(Tabla1[[#This Row],[Relleno]:[Cromado3]],"TS")+COUNTIF(Tabla1[[#This Row],[Relleno]:[Cromado3]],"X")),0) -> 0
A10: 261224 | B10: UNIMAQ | C10: CILINDRO DE HYD | D10: 1221 | I10: FUERA DE PROGRAMA | AT10: =IFERROR((COUNTIF(Tabla1[[#This Row],[Relleno]:[Cromado3]],"OK")*1+COUNTIF(Tabla1[[#This Row],[Relleno]:[Cromado3]],"PR")*0.5+COUNTIF(Tabla1[[#This Row],[Relleno]:[Cromado3]],"TS")*0.05)/(COUNTIF(Tabla1[[#This Row],[Relleno]:[Cromado3]],"OK")+COUNTIF(Tabla1[[#This Row],[Relleno]:[Cromado3]],"PR")+COUNTIF(Tabla1[[#This Row],[Relleno]:[Cromado3]],"TS")+COUNTIF(Tabla1[[#This Row],[Relleno]:[Cromado3]],"X")),0) -> 0
A11: 261324 | B11: UNIMAQ | C11: CILINDRO DE HYD | D11: 1220 | I11: FUERA DE PROGRAMA | AT11: =IFERROR((COUNTIF(Tabla1[[#This Row],[Relleno]:[Cromado3]],"OK")*1+COUNTIF(Tabla1[[#This Row],[Relleno]:[Cromado3]],"PR")*0.5+COUNTIF(Tabla1[[#This Row],[Relleno]:[Cromado3]],"TS")*0.05)/(COUNTIF(Tabla1[[#This Row],[Relleno]:[Cromado3]],"OK")+COUNTIF(Tabla1[[#This Row],[Relleno]:[Cromado3]],"PR")+COUNTIF(Tabla1[[#This Row],[Relleno]:[Cromado3]],"TS")+COUNTIF(Tabla1[[#This Row],[Relleno]:[Cromado3]],"X")),0) -> 0
A12: 261424 | B12: UNIMAQ | C12: CILINDRO DE HYD | D12: 1220 | I12: FUERA DE PROGRAMA | AT12: =IFERROR((COUNTIF(Tabla1[[#This Row],[Relleno]:[Cromado3]],"OK")*1+COUNTIF(Tabla1[[#This Row],[Relleno]:[Cromado3]],"PR")*0.5+COUNTIF(Tabla1[[#This Row],[Relleno]:[Cromado3]],"TS")*0.05)/(COUNTIF(Tabla1[[#This Row],[Relleno]:[Cromado3]],"OK")+COUNTIF(Tabla1[[#This Row],[Relleno]:[Cromado3]],"PR")+COUNTIF(Tabla1[[#This Row],[Relleno]:[Cromado3]],"TS")+COUNTIF(Tabla1[[#This Row],[Relleno]:[Cromado3]],"X")),0) -> 0
A13: 266824 | B13: UNIMAQ | C13: CILINDRO DE LEVANTE | D13: 1150 | I13: FUERA DE PROGRAMA | AT13: =IFERROR((COUNTIF(Tabla1[[#This Row],[Relleno]:[Cromado3]],"OK")*1+COUNTIF(Tabla1[[#This Row],[Relleno]:[Cromado3]],"PR")*0.5+COUNTIF(Tabla1[[#This Row],[Relleno]:[Cromado3]],"TS")*0.05)/(COUNTIF(Tabla1[[#This Row],[Relleno]:[Cromado3]],"OK")+COUNTIF(Tabla1[[#This Row],[Relleno]:[Cromado3]],"PR")+COUNTIF(Tabla1[[#This Row],[Relleno]:[Cromado3]],"TS")+COUNTIF(Tabla1[[#This Row],[Relleno]:[Cromado3]],"X")),0) -> 0
A14: 273924 | B14: ANTAPACCAY | C14: CILINDRO DE SUSPENSION POSTERIOR | D14: 797F | I14: LISTO PARA DESPACHO | P14: OK | Q14: OK | S14: OK | U14: OK | V14: OK | W14: OK | AF14: OK | AG14: OK | AH14: OK | AJ14: OK | AK14: OK | AT14: =IFERROR((COUNTIF(Tabla1[[#This Row],[Relleno]:[Cromado3]],"OK")*1+COUNTIF(Tabla1[[#This Row],[Relleno]:[Cromado3]],"PR")*0.5+COUNTIF(Tabla1[[#This Row],[Relleno]:[Cromado3]],"TS")*0.05)/(COUNTIF(Tabla1[[#This Row],[Relleno]:[Cromado3]],"OK")+COUNTIF(Tabla1[[#This Row],[Relleno]:[Cromado3]],"PR")+COUNTIF(Tabla1[[#This Row],[Relleno]:[Cromado3]],"TS")+COUNTIF(Tabla1[[#This Row],[Relleno]:[Cromado3]],"X")),0) -> 1
A15: 275424 | B15: BAMBAS | C15: CILINDRO DE LEVANTE DE TOLVA | D15: 930E-4SE | F15: 4400570845 | I15: ENTREGADO | AT15: =IFERROR((COUNTIF(Tabla1[[#This Row],[Relleno]:[Cromado3]],"OK")*1+COUNTIF(Tabla1[[#This Row],[Relleno]:[Cromado3]],"PR")*0.5+COUNTIF(Tabla1[[#This Row],[Relleno]:[Cromado3]],"TS")*0.05)/(COUNTIF(Tabla1[[#This Row],[Relleno]:[Cromado3]],"OK")+COUNTIF(Tabla1[[#This Row],[Relleno]:[Cromado3]],"PR")+COUNTIF(Tabla1[[#This Row],[Relleno]:[Cromado3]],"TS")+COUNTIF(Tabla1[[#This Row],[Relleno]:[Cromado3]],"X")),0) -> 0
A16: 279224 | B16: UNIMAQ | C16: CILINDRO HIDRAULICO DE MANIPULADOR | D16: GENERICO | I16: FUERA DE PROGRAMA | T16: X | W16: X | AC16: X | AD16: OK | AJ16: X | AK16: X | AT16: =IFERROR((COUNTIF(Tabla1[[#This Row],[Relleno]:[Cromado3]],"OK")*1+COUNTIF(Tabla1[[#This Row],[Relleno]:[Cromado3]],"PR")*0.5+COUNTIF(Tabla1[[#This Row],[Relleno]:[Cromado3]],"TS")*0.05)/(COUNTIF(Tabla1[[#This Row],[Relleno]:[Cromado3]],"OK")+COUNTIF(Tabla1[[#This Row],[Relleno]:[Cromado3]],"PR")+COUNTIF(Tabla1[[#This Row],[Relleno]:[Cromado3]],"TS")+COUNTIF(Tabla1[[#This Row],[Relleno]:[Cromado3]],"X")),0) -> 0.16666667
A17: 279624 | B17: ANTAPACCAY | C17: CILINDRO DE SUSPENSION POSTERIOR | D17: 797F | F17: 4500512788 | I17: LISTO PARA DESPACHO | P17: OK | Q17: OK | S17: OK | U17: OK | V17: OK | W17: OK | AD17: TS | AG17: OK | AJ17: OK | AK17: OK | AT17: =IFERROR((COUNTIF(Tabla1[[#This Row],[Relleno]:[Cromado3]],"OK")*1+COUNTIF(Tabla1[[#This Row],[Relleno]:[Cromado3]],"PR")*0.5+COUNTIF(Tabla1[[#This Row],[Relleno]:[Cromado3]],"TS")*0.05)/(COUNTIF(Tabla1[[#This Row],[Relleno]:[Cromado3]],"OK")+COUNTIF(Tabla1[[#This Row],[Relleno]:[Cromado3]],"PR")+COUNTIF(Tabla1[[#This Row],[Relleno]:[Cromado3]],"TS")+COUNTIF(Tabla1[[#This Row],[Relleno]:[Cromado3]],"X")),0) -> 0.905
A18: 281024 | B18: ANTAPACCAY | C18: CILINDRO HIDRAULICO DE CLAM | D18: 6060FS | F18: 4500514311 | I18: LISTO PARA DESPACHO | N18: OK | O18: OK | P18: OK | Q18: OK | R18: OK | S18: OK | W18: OK | AD18: X | AG18: X | AJ18: X | AK18: X | AT18: =IFERROR((COUNTIF(Tabla1[[#This Row],[Relleno]:[Cromado3]],"OK")*1+COUNTIF(Tabla1[[#This Row],[Relleno]:[Cromado3]],"PR")*0.5+COUNTIF(Tabla1[[#This Row],[Relleno]:[Cromado3]],"TS")*0.05)/(COUNTIF(Tabla1[[#This Row],[Relleno]:[Cromado3]],"OK")+COUNTIF(Tabla1[[#This Row],[Relleno]:[Cromado3]],"PR")+COUNTIF(Tabla1[[#This Row],[Relleno]:[Cromado3]],"TS")+COUNTIF(Tabla1[[#This Row],[Relleno]:[Cromado3]],"X")),0) -> 0.63636364
A19: 281224 | B19: ANTAPACCAY | C19: CILINDRO DE LEVANTE | D19: 988K | F19: 4500515962 | I19: LISTO PARA DESPACHO | N19: OK | W19: OK | AD19: OK | AG19: OK | AJ19: OK | AK19: OK | AT19: =IFERROR((COUNTIF(Tabla1[[#This Row],[Relleno]:[Cromado3]],"OK")*1+COUNTIF(Tabla1[[#This Row],[Relleno]:[Cromado3]],"PR")*0.5+COUNTIF(Tabla1[[#This Row],[Relleno]:[Cromado3]],"TS")*0.05)/(COUNTIF(Tabla1[[#This Row],[Relleno]:[Cromado3]],"OK")+COUNTIF(Tabla1[[#This Row],[Relleno]:[Cromado3]],"PR")+COUNTIF(Tabla1[[#This Row],[Relleno]:[Cromado3]],"TS")+COUNTIF(Tabla1[[#This Row],[Relleno]:[Cromado3]],"X")),0) -> 1
A20: 282824 | B20: BAMBAS | C20: FRENO DELANTERO | D20: 24 | F20: 4400579125 | I20: ENTREGADO | AJ20: OK | AK20: OK | AT20: =IFERROR((COUNTIF(Tabla1[[#This Row],[Relleno]:[Cromado3]],"OK")*1+COUNTIF(Tabla1[[#This Row],[Relleno]:[Cromado3]],"PR")*0.5+COUNTIF(Tabla1[[#This Row],[Relleno]:[Cromado3]],"TS")*0.05)/(COUNTIF(Tabla1[[#This Row],[Relleno]:[Cromado3]],"OK")+COUNTIF(Tabla1[[#This Row],[Relleno]:[Cromado3]],"PR")+COUNTIF(Tabla1[[#This Row],[Relleno]:[Cromado3]],"TS")+COUNTIF(Tabla1[[#This Row],[Relleno]:[Cromado3]],"X")),0) -> 1
A21: 282924 | B21: BAMBAS | C21: FRENO DELANTERO | D21: 24 | F21: 4400579126 | I21: ENTREGADO | AJ21: OK | AK21: OK | AT21: =IFERROR((COUNTIF(Tabla1[[#This Row],[Relleno]:[Cromado3]],"OK")*1+COUNTIF(Tabla1[[#This Row],[Relleno]:[Cromado3]],"PR")*0.5+COUNTIF(Tabla1[[#This Row],[Relleno]:[Cromado3]],"TS")*0.05)/(COUNTIF(Tabla1[[#This Row],[Relleno]:[Cromado3]],"OK")+COUNTIF(Tabla1[[#This Row],[Relleno]:[Cromado3]],"PR")+COUNTIF(Tabla1[[#This Row],[Relleno]:[Cromado3]],"TS")+COUNTIF(Tabla1[[#This Row],[Relleno]:[Cromado3]],"X")),0) -> 1
A22: 283724 | B22: ANTAPACCAY | C22: CILINDRO DE LEVANTE DE BULLDOZER | D22: D11T | F22: 4500518233 | I22: ENTREGADO | N22: OK | U22: OK | V22: OK | W22: OK | AD22: OK | AG22: OK | AJ22: OK | AK22: OK | AT22: =IFERROR((COUNTIF(Tabla1[[#This Row],[Relleno]:[Cromado3]],"OK")*1+COUNTIF(Tabla1[[#This Row],[Relleno]:[Cromado3]],"PR")*0.5+COUNTIF(Tabla1[[#This Row],[Relleno]:[Cromado3]],"TS")*0.05)/(COUNTIF(Tabla1[[#This Row],[Relleno]:[Cromado3]],"OK")+COUNTIF(Tabla1[[#This Row],[Relleno]:[Cromado3]],"PR")+COUNTIF(Tabla1[[#This Row],[Relleno]:[Cromado3]],"TS")+COUNTIF(Tabla1[[#This Row],[Relleno]:[Cromado3]],"X")),0) -> 1
A23: 284024 | B23: BAMBAS | C23: CILINDRO DE STICK | D23: 390DL | F23: 4400580039 | I23: ENTREGADO | L23: OK | M23: OK | N23: OK | U23: OK | V23: OK | X23: OK | Y23: OK | Z23: OK | AA23: OK | AD23: OK | AG23: OK | AJ23: OK | AK23: OK | AT23: =IFERROR((COUNTIF(Tabla1[[#This Row],[Relleno]:[Cromado3]],"OK")*1+COUNTIF(Tabla1[[#This Row],[Relleno]:[Cromado3]],"PR")*0.5+COUNTIF(Tabla1[[#This Row],[Relleno]:[Cromado3]],"TS")*0.05)/(COUNTIF(Tabla1[[#This Row],[Relleno]:[Cromado3]],"OK")+COUNTIF(Tabla1[[#This Row],[Relleno]:[Cromado3]],"PR")+COUNTIF(Tabla1[[#This Row],[Relleno]:[Cromado3]],"TS")+COUNTIF(Tabla1[[#This Row],[Relleno]:[Cromado3]],"X")),0) -> 1
A24: 284124 | B24: BAMBAS | C24: CILINDRO DE INCLINACION DE BULLDOZER | D24: D475 | F24: 4400580037 | I24: ENTREGADO | L24: OK | M24: OK | P24: OK | Q24: OK | S24: OK | T24: OK | U24: OK | V24: OK | W24: OK | AD24: OK | AE24: OK | AG24: OK | AJ24: OK | AK24: OK | AT24: =IFERROR((COUNTIF(Tabla1[[#This Row],[Relleno]:[Cromado3]],"OK")*1+COUNTIF(Tabla1[[#This Row],[Relleno]:[Cromado3]],"PR")*0.5+COUNTIF(Tabla1[[#This Row],[Relleno]:[Cromado3]],"TS")*0.05)/(COUNTIF(Tabla1[[#This Row],[Relleno]:[Cromado3]],"OK")+COUNTIF(Tabla1[[#This Row],[Relleno]:[Cromado3]],"PR")+COUNTIF(Tabla1[[#This Row],[Relleno]:[Cromado3]],"TS")+COUNTIF(Tabla1[[#This Row],[Relleno]:[Cromado3]],"X")),0) -> 1
A25: 284224 | B25: BAMBAS | C25: CILINDRO DE DIRECCION | D25: 930E-4SE | F25: 4400580038 | I25: ENTREGADO | AT25: =IFERROR((COUNTIF(Tabla1[[#This Row],[Relleno]:[Cromado3]],"OK")*1+COUNTIF(Tabla1[[#This Row],[Relleno]:[Cromado3]],"PR")*0.5+COUNTIF(Tabla1[[#This Row],[Relleno]:[Cromado3]],"TS")*0.05)/(COUNTIF(Tabla1[[#This Row],[Relleno]:[Cromado3]],"OK")+COUNTIF(Tabla1[[#This Row],[Relleno]:[Cromado3]],"PR")+COUNTIF(Tabla1[[#This Row],[Relleno]:[Cromado3]],"TS")+COUNTIF(Tabla1[[#This Row],[Relleno]:[Cromado3]],"X")),0) -> 0
A26: 284524 | B26: BAMBAS | C26: CILINDRO DE INCLINACION DE BULLDOZER | D26: 844H | F26: 4400580457 | I26: ENTREGADO | L26: OK | M26: OK | N26: OK | O26: OK | U26: OK | V26: OK | W26: OK | AD26: OK | AE26: OK | AG26: OK | AJ26: OK | AK26: OK | AT26: =IFERROR((COUNTIF(Tabla1[[#This Row],[Relleno]:[Cromado3]],"OK")*1+COUNTIF(Tabla1[[#This Row],[Relleno]:[Cromado3]],"PR")*0.5+COUNTIF(Tabla1[[#This Row],[Relleno]:[Cromado3]],"TS")*0.05)/(COUNTIF(Tabla1[[#This Row],[Relleno]:[Cromado3]],"OK")+COUNTIF(Tabla1[[#This Row],[Relleno]:[Cromado3]],"PR")+COUNTIF(Tabla1[[#This Row],[Relleno]:[Cromado3]],"TS")+COUNTIF(Tabla1[[#This Row],[Relleno]:[Cromado3]],"X")),0) -> 1
A27: 284624 | B27: BAMBAS | C27: CILINDRO DE LEVANTE DE BULLDOZER | D27: D475 | F27: 4400580466 | I27: ENTREGADO | AT27: =IFERROR((COUNTIF(Tabla1[[#This Row],[Relleno]:[Cromado3]],"OK")*1+COUNTIF(Tabla1[[#This Row],[Relleno]:[Cromado3]],"PR")*0.5+COUNTIF(Tabla1[[#This Row],[Relleno]:[Cromado3]],"TS")*0.05)/(COUNTIF(Tabla1[[#This Row],[Relleno]:[Cromado3]],"OK")+COUNTIF(Tabla1[[#This Row],[Relleno]:[Cromado3]],"PR")+COUNTIF(Tabla1[[#This Row],[Relleno]:[Cromado3]],"TS")+COUNTIF(Tabla1[[#This Row],[Relleno]:[Cromado3]],"X")),0) -> 0
A28: 284724 | B28: BAMBAS | C28: CILINDRO DE LEVANTE DE BULLDOZER | D28: D475 | F28: 4400580467 | I28: ENTREGADO | N28: OK | P28: OK | Q28: OK | S28: OK | T28: OK | U28: OK | V28: OK | X28: OK | Y28: OK | Z28: OK | AA28: OK | AD28: OK | AG28: OK | AJ28: OK | AK28: OK | AS28: ESTA ARMADO EL V´STAGO CON TAPA Y PSITON + SELLOS | AT28: =IFERROR((COUNTIF(Tabla1[[#This Row],[Relleno]:[Cromado3]],"OK")*1+COUNTIF(Tabla1[[#This Row],[Relleno]:[Cromado3]],"PR")*0.5+COUNTIF(Tabla1[[#This Row],[Relleno]:[Cromado3]],"TS")*0.05)/(COUNTIF(Tabla1[[#This Row],[Relleno]:[Cromado3]],"OK")+COUNTIF(Tabla1[[#This Row],[Relleno]:[Cromado3]],"PR")+COUNTIF(Tabla1[[#This Row],[Relleno]:[Cromado3]],"TS")+COUNTIF(Tabla1[[#This Row],[Relleno]:[Cromado3]],"X")),0) -> 1
A29: 285124 | B29: ANTAPACCAY | C29: CILINDRO DE LEVANTE DE RIPPER | D29: D11 | F29: 4500519627 | I29: ENTREGADO | AT29: =IFERROR((COUNTIF(Tabla1[[#This Row],[Relleno]:[Cromado3]],"OK")*1+COUNTIF(Tabla1[[#This Row],[Relleno]:[Cromado3]],"PR")*0.5+COUNTIF(Tabla1[[#This Row],[Relleno]:[Cromado3]],"TS")*0.05)/(COUNTIF(Tabla1[[#This Row],[Relleno]:[Cromado3]],"OK")+COUNTIF(Tabla1[[#This Row],[Relleno]:[Cromado3]],"PR")+COUNTIF(Tabla1[[#This Row],[Relleno]:[Cromado3]],"TS")+COUNTIF(Tabla1[[#This Row],[Relleno]:[Cromado3]],"X")),0) -> 0
A30: 285224 | B30: ANTAPACCAY | C30: CILINDRO DE INCLINACION DE BULLDOZER | D30: D11T | F30: 4500519625 | I30: ENTREGADO | L30: OK | M30: OK | N30: OK | O30: OK | P30: OK | Q30: OK | S30: OK | U30: OK | V30: OK | W30: OK | AD30: OK | AG30: OK | AJ30: OK | AK30: X | AT30: =IFERROR((COUNTIF(Tabla1[[#This Row],[Relleno]:[Cromado3]],"OK")*1+COUNTIF(Tabla1[[#This Row],[Relleno]:[Cromado3]],"PR")*0.5+COUNTIF(Tabla1[[#This Row],[Relleno]:[Cromado3]],"TS")*0.05)/(COUNTIF(Tabla1[[#This Row],[Relleno]:[Cromado3]],"OK")+COUNTIF(Tabla1[[#This Row],[Relleno]:[Cromado3]],"PR")+COUNTIF(Tabla1[[#This Row],[Relleno]:[Cromado3]],"TS")+COUNTIF(Tabla1[[#This Row],[Relleno]:[Cromado3]],"X")),0) -> 0.92857143
A31: 285324 | B31: ANTAPACCAY | C31: CILINDRO DE DIRECCION | D31: 24 | F31: 4500519626 | I31: LISTO PARA DESPACHO | L31: OK | M31: OK | N31: OK | O31: OK | P31: OK | Q31: OK | S31: OK | U31: OK | V31: OK | X31: OK | Y31: OK | Z31: OK | AA31: OK | AC31: ESPERA DE BARRA CROMADA | AD31: OK | AG31: OK | AJ31: PR | AK31: X | AT31: =IFERROR((COUNTIF(Tabla1[[#This Row],[Relleno]:[Cromado3]],"OK")*1+COUNTIF(Tabla1[[#This Row],[Relleno]:[Cromado3]],"PR")*0.5+COUNTIF(Tabla1[[#This Row],[Relleno]:[Cromado3]],"TS")*0.05)/(COUNTIF(Tabla1[[#This Row],[Relleno]:[Cromado3]],"OK")+COUNTIF(Tabla1[[#This Row],[Relleno]:[Cromado3]],"PR")+COUNTIF(Tabla1[[#This Row],[Relleno]:[Cromado3]],"TS")+COUNTIF(Tabla1[[#This Row],[Relleno]:[Cromado3]],"X")),0) -> 0.91176471
A32: 285524 | B32: ANTAPACCAY | C32: CILINDRO DE DIRECCION | D32: HD1500 | F32: 4500520946 | I32: LISTO PARA DESPACHO | L32: OK | M32: OK | N32: OK | P32: OK | Q32: OK | S32: OK | U32: OK | V32: OK | W32: OK | AD32: OK | AG32: OK | AJ32: OK | AK32: TS | AT32: =IFERROR((COUNTIF(Tabla1[[#This Row],[Relleno]:[Cromado3]],"OK")*1+COUNTIF(Tabla1[[#This Row],[Relleno]:[Cromado3]],"PR")*0.5+COUNTIF(Tabla1[[#This Row],[Relleno]:[Cromado3]],"TS")*0.05)/(COUNTIF(Tabla1[[#This Row],[Relleno]:[Cromado3]],"OK")+COUNTIF(Tabla1[[#This Row],[Relleno]:[Cromado3]],"PR")+COUNTIF(Tabla1[[#This Row],[Relleno]:[Cromado3]],"TS")+COUNTIF(Tabla1[[#This Row],[Relleno]:[Cromado3]],"X")),0) -> 0.92692308
A33: 285724 | B33: ANTAPACCAY | C33: CILINDRO DE LEVANTE | D33: 994F | E33: 21 | F33: 4500520964 | I33: ENTREGADO | N33: OK | P33: OK | Q33: OK | S33: OK | U33: OK | V33: OK | W33: OK | AD33: OK | AG33: OK | AJ33: TS | AK33: X | AT33: =IFERROR((COUNTIF(Tabla1[[#This Row],[Relleno]:[Cromado3]],"OK")*1+COUNTIF(Tabla1[[#This Row],[Relleno]:[Cromado3]],"PR")*0.5+COUNTIF(Tabla1[[#This Row],[Relleno]:[Cromado3]],"TS")*0.05)/(COUNTIF(Tabla1[[#This Row],[Relleno]:[Cromado3]],"OK")+COUNTIF(Tabla1[[#This Row],[Relleno]:[Cromado3]],"PR")+COUNTIF(Tabla1[[#This Row],[Relleno]:[Cromado3]],"TS")+COUNTIF(Tabla1[[#This Row],[Relleno]:[Cromado3]],"X")),0) -> 0.82272727
A34: 286024 | B34: ANTAPACCAY | C34: CILINDRO DE DIRECCION | D34: 930E-4SE | F34: 4500522025 | I34: LISTO PARA DESPACHO | L34: OK | M34: OK | N34: OK | X34: OK | Y34: OK | Z34: OK | AA34: OK | AD34: OK | AI34: OK | AJ34: OK | AK34: X | AT34: =IFERROR((COUNTIF(Tabla1[[#This Row],[Relleno]:[Cromado3]],"OK")*1+COUNTIF(Tabla1[[#This Row],[Relleno]:[Cromado3]],"PR")*0.5+COUNTIF(Tabla1[[#This Row],[Relleno]:[Cromado3]],"TS")*0.05)/(COUNTIF(Tabla1[[#This Row],[Relleno]:[Cromado3]],"OK")+COUNTIF(Tabla1[[#This Row],[Relleno]:[Cromado3]],"PR")+COUNTIF(Tabla1[[#This Row],[Relleno]:[Cromado3]],"TS")+COUNTIF(Tabla1[[#This Row],[Relleno]:[Cromado3]],"X")),0) -> 0.90909091
A35: 286624 | B35: BAMBAS | C35: CILINDRO DE INCLINACION DE BULLDOZER | D35: D11T | F35: 4400583123 | I35: ENTREGADO | L35: OK | M35: OK | P35: OK | Q35: OK | S35: OK | U35: OK | V35: OK | W35: OK | AD35: OK | AE35: CAMBIO DE TAPA CON LA 285224 | AG35: OK | AH35: CAMBIO DE PISTON CON LA 285224 | AJ35: OK | AK35: OK | AT35: =IFERROR((COUNTIF(Tabla1[[#This Row],[Relleno]:[Cromado3]],"OK")*1+COUNTIF(Tabla1[[#This Row],[Relleno]:[Cromado3]],"PR")*0.5+COUNTIF(Tabla1[[#This Row],[Relleno]:[Cromado3]],"TS")*0.05)/(COUNTIF(Tabla1[[#This Row],[Relleno]:[Cromado3]],"OK")+COUNTIF(Tabla1[[#This Row],[Relleno]:[Cromado3]],"PR")+COUNTIF(Tabla1[[#This Row],[Relleno]:[Cromado3]],"TS")+COUNTIF(Tabla1[[#This Row],[Relleno]:[Cromado3]],"X")),0) -> 1
A36: 286724 | B36: ANTAPACCAY | C36: ACUMULADOR DE DIRECCION | D36: 797F | F36: 4500524867 | I36: ENTREGADO | AT36: =IFERROR((COUNTIF(Tabla1[[#This Row],[Relleno]:[Cromado3]],"OK")*1+COUNTIF(Tabla1[[#This Row],[Relleno]:[Cromado3]],"PR")*0.5+COUNTIF(Tabla1[[#This Row],[Relleno]:[Cromado3]],"TS")*0.05)/(COUNTIF(Tabla1[[#This Row],[Relleno]:[Cromado3]],"OK")+COUNTIF(Tabla1[[#This Row],[Relleno]:[Cromado3]],"PR")+COUNTIF(Tabla1[[#This Row],[Relleno]:[Cromado3]],"TS")+COUNTIF(Tabla1[[#This Row],[Relleno]:[Cromado3]],"X")),0) -> 0
A37: 286824 | B37: ANTAPACCAY | C37: ACUMULADOR DE DIRECCION | D37: 797F | F37: 4500524408 | I37: ENTREGADO | AT37: =IFERROR((COUNTIF(Tabla1[[#This Row],[Relleno]:[Cromado3]],"OK")*1+COUNTIF(Tabla1[[#This Row],[Relleno]:[Cromado3]],"PR")*0.5+COUNTIF(Tabla1[[#This Row],[Relleno]:[Cromado3]],"TS")*0.05)/(COUNTIF(Tabla1[[#This Row],[Relleno]:[Cromado3]],"OK")+COUNTIF(Tabla1[[#This Row],[Relleno]:[Cromado3]],"PR")+COUNTIF(Tabla1[[#This Row],[Relleno]:[Cromado3]],"TS")+COUNTIF(Tabla1[[#This Row],[Relleno]:[Cromado3]],"X")),0) -> 0
A38: 286924 | B38: ANTAPACCAY | C38: ACUMULADOR DE DIRECCION | D38: 797F | F38: 4500524410 | I38: ENTREGADO | AT38: =IFERROR((COUNTIF(Tabla1[[#This Row],[Relleno]:[Cromado3]],"OK")*1+COUNTIF(Tabla1[[#This Row],[Relleno]:[Cromado3]],"PR")*0.5+COUNTIF(Tabla1[[#This Row],[Relleno]:[Cromado3]],"TS")*0.05)/(COUNTIF(Tabla1[[#This Row],[Relleno]:[Cromado3]],"OK")+COUNTIF(Tabla1[[#This Row],[Relleno]:[Cromado3]],"PR")+COUNTIF(Tabla1[[#This Row],[Relleno]:[Cromado3]],"TS")+COUNTIF(Tabla1[[#This Row],[Relleno]:[Cromado3]],"X")),0) -> 0
A39: 287024 | B39: ANTAPACCAY | C39: CILINDRO DE LEVANTE DE BULLDOZER | D39: D475 | F39: 4500524754 | I39: LISTO PARA DESPACHO | N39: OK | P39: OK | Q39: OK | T39: OK | X39: OK | Y39: OK | Z39: OK | AA39: OK | AC39: OK | AD39: OK | AG39: OK | AJ39: OK | AT39: =IFERROR((COUNTIF(Tabla1[[#This Row],[Relleno]:[Cromado3]],"OK")*1+COUNTIF(Tabla1[[#This Row],[Relleno]:[Cromado3]],"PR")*0.5+COUNTIF(Tabla1[[#This Row],[Relleno]:[Cromado3]],"TS")*0.05)/(COUNTIF(Tabla1[[#This Row],[Relleno]:[Cromado3]],"OK")+COUNTIF(Tabla1[[#This Row],[Relleno]:[Cromado3]],"PR")+COUNTIF(Tabla1[[#This Row],[Relleno]:[Cromado3]],"TS")+COUNTIF(Tabla1[[#This Row],[Relleno]:[Cromado3]],"X")),0) -> 1
A40: 287124 | B40: ANTAPACCAY | C40: CILINDRO DE INCLINACION DE RIPPER | D40: D11T | F40: 4500525793 | I40: ENTREGADO | L40: OK | M40: OK | N40: OK | U40: OK | V40: OK | W40: OK | AD40: OK | AE40: OK | AG40: OK | AJ40: OK | AK40: TS | AT40: =IFERROR((COUNTIF(Tabla1[[#This Row],[Relleno]:[Cromado3]],"OK")*1+COUNTIF(Tabla1[[#This Row],[Relleno]:[Cromado3]],"PR")*0.5+COUNTIF(Tabla1[[#This Row],[Relleno]:[Cromado3]],"TS")*0.05)/(COUNTIF(Tabla1[[#This Row],[Relleno]:[Cromado3]],"OK")+COUNTIF(Tabla1[[#This Row],[Relleno]:[Cromado3]],"PR")+COUNTIF(Tabla1[[#This Row],[Relleno]:[Cromado3]],"TS")+COUNTIF(Tabla1[[#This Row],[Relleno]:[Cromado3]],"X")),0) -> 0.91363636
A41: 287224 | B41: ANTAPACCAY | C41: CILINDRO DE INCLINACION DE RIPPER | D41: D11T | F41: 4500525794 | I41: ENTREGADO | L41: OK | M41: OK | N41: OK | U41: OK | V41: OK | W41: OK | AD41: OK | AG41: OK | AJ41: OK | AK41: TS | AT41: =IFERROR((COUNTIF(Tabla1[[#This Row],[Relleno]:[Cromado3]],"OK")*1+COUNTIF(Tabla1[[#This Row],[Relleno]:[Cromado3]],"PR")*0.5+COUNTIF(Tabla1[[#This Row],[Relleno]:[Cromado3]],"TS")*0.05)/(COUNTIF(Tabla1[[#This Row],[Relleno]:[Cromado3]],"OK")+COUNTIF(Tabla1[[#This Row],[Relleno]:[Cromado3]],"PR")+COUNTIF(Tabla1[[#This Row],[Relleno]:[Cromado3]],"TS")+COUNTIF(Tabla1[[#This Row],[Relleno]:[Cromado3]],"X")),0) -> 0.905
...

Sheet Programa
B2: OT | C2: DESCRIPCION | D2: MODELO | E2: Nombre de tarea | F2: Nombres de los recursos | G2: Duración | H2: Comienzo | I2: Fin | J2: % trabajo completado
B3: OT | C3: DESCRIPCION | D3: MODELO | E3: TORNO 1 | F3: Gabriel Anco | G3: 5.53 días | H3: lun 30/09/24 | I3: lun 7/10/24 | J3: 0.36
B4: 287724 | C4: =_xlfn.XLOOKUP(B4,PLANEAMIENTO!A:A,PLANEAMIENTO!C:C) -> CILINDRO DE JACK HYD | D4: =_xlfn.XLOOKUP(B4,PLANEAMIENTO!A:A,PLANEAMIENTO!D:D) -> PITVIPER 351 | E4: Corte de tapa de cilindro | F4: Gabriel Anco | G4: 4 horas | H4: jue 3/10/24 | I4: jue 3/10/24 | J4: 0.2
B5: 286624 | C5: =_xlfn.XLOOKUP(B5,PLANEAMIENTO!A:A,PLANEAMIENTO!C:C) -> CILINDRO DE INCLINACION DE BULLDOZER | D5: =_xlfn.XLOOKUP(B5,PLANEAMIENTO!A:A,PLANEAMIENTO!D:D) -> D11T | E5: Maquinado de diámetro de salida de cilindro | F5: Gabriel Anco | G5: 3 horas | H5: jue 3/10/24 | I5: jue 3/10/24 | J5: 0
B6: 287824 | C6: =_xlfn.XLOOKUP(B6,PLANEAMIENTO!A:A,PLANEAMIENTO!C:C) -> CILINDRO DE JACK HYD | D6: =_xlfn.XLOOKUP(B6,PLANEAMIENTO!A:A,PLANEAMIENTO!D:D) -> PITVIPER 351 | E6: Corte de tapa de cilindro | F6: Gabriel Anco | G6: 4.5 horas | H6: jue 3/10/24 | I6: vie 4/10/24 | J6: 0
B7: 288324 | C7: =_xlfn.XLOOKUP(B7,PLANEAMIENTO!A:A,PLANEAMIENTO!C:C) -> CILINDRO DE INCLINACION DE BULLDOZER | D7: =_xlfn.XLOOKUP(B7,PLANEAMIENTO!A:A,PLANEAMIENTO!D:D) -> D11T | E7: Corte de cilindro | F7: Gabriel Anco | G7: 7 horas | H7: vie 4/10/24 | I7: lun 7/10/24 | J7: 0
B8: 288324 | C8: =_xlfn.XLOOKUP(B8,PLANEAMIENTO!A:A,PLANEAMIENTO!C:C) -> CILINDRO DE INCLINACION DE BULLDOZER | D8: =_xlfn.XLOOKUP(B8,PLANEAMIENTO!A:A,PLANEAMIENTO!D:D) -> D11T | E8: Maquinado de encastre de cilindro | F8: Gabriel Anco | G8: 7 horas | H8: lun 7/10/24 | I8: lun 7/10/24 | J8: 0
B9: OT | C9: DESCRIPCION | D9: MODELO | E9: TORNO 2 | F9: Rolando Yaique | G9: 4.42 días | H9: mar 1/10/24 | I9: lun 7/10/24 | J9: 0.19
B10: 287024 | C10: =_xlfn.XLOOKUP(B10,PLANEAMIENTO!A:A,PLANEAMIENTO!C:C) -> CILINDRO DE LEVANTE DE BULLDOZER | D10: =_xlfn.XLOOKUP(B10,PLANEAMIENTO!A:A,PLANEAMIENTO!D:D) -> D475 | E10: Fabricación de cojinetes | F10: Rolando Yaique | G10: 2 días | H10: mié 2/10/24 | I10: vie 4/10/24 | J10: 0.2
B11: 287324 | C11: =_xlfn.XLOOKUP(B11,PLANEAMIENTO!A:A,PLANEAMIENTO!C:C) -> CILINDRO DE DIRECCION | D11: =_xlfn.XLOOKUP(B11,PLANEAMIENTO!A:A,PLANEAMIENTO!D:D) -> 24 | E11: Maquinado de rosca de cilindro | F11: Rolando Yaique | G11: 4.5 horas | H11: vie 4/10/24 | I11: vie 4/10/24 | J11: 0
B12: 286024 | C12: =_xlfn.XLOOKUP(B12,PLANEAMIENTO!A:A,PLANEAMIENTO!C:C) -> CILINDRO DE DIRECCION | D12: =_xlfn.XLOOKUP(B12,PLANEAMIENTO!A:A,PLANEAMIENTO!D:D) -> 930E-4SE | E12: Fabricacion de piston | F12: Rolando Yaique | G12: 1 día | H12: vie 4/10/24 | I12: lun 7/10/24 | J12: 0
B13: OT | C13: DESCRIPCION | D13: MODELO | E13: TORNO 3 | F13: Luis Ramos | G13: 4.84 días? | H13: lun 30/09/24 | I13: lun 7/10/24 | J13: 0.65
B14: 291524 | C14: =_xlfn.XLOOKUP(B14,PLANEAMIENTO!A:A,PLANEAMIENTO!C:C) -> CILINDRO DE INCLINACION DE BULLDOZER | D14: =_xlfn.XLOOKUP(B14,PLANEAMIENTO!A:A,PLANEAMIENTO!D:D) -> 844H | E14: Corte de vastago | F14: Luis Ramos | G14: 2.5 horas | H14: mié 2/10/24 | I14: jue 3/10/24 | J14: 0.7
B15: 291324 | C15: =_xlfn.XLOOKUP(B15,PLANEAMIENTO!A:A,PLANEAMIENTO!C:C) -> CILINDRO DE LEVANTE DE BULLDOZER | D15: =_xlfn.XLOOKUP(B15,PLANEAMIENTO!A:A,PLANEAMIENTO!D:D) -> 844H | E15: Corte de vastago | F15: Luis Ramos | G15: 2.5 horas | H15: jue 3/10/24 | I15: jue 3/10/24 | J15: 0
B16: 291624 | C16: =_xlfn.XLOOKUP(B16,PLANEAMIENTO!A:A,PLANEAMIENTO!C:C) -> CILINDRO DE LEVANTE DE BULLDOZER | D16: =_xlfn.XLOOKUP(B16,PLANEAMIENTO!A:A,PLANEAMIENTO!D:D) -> 844H | E16: Corte de vastago | F16: Luis Ramos | G16: 2.5 horas | H16: jue 3/10/24 | I16: jue 3/10/24 | J16: 0
B17: 289524 | C17: =_xlfn.XLOOKUP(B17,PLANEAMIENTO!A:A,PLANEAMIENTO!C:C) -> CILINDRO DE LEVANTE DE BULLDOZER | D17: =_xlfn.XLOOKUP(B17,PLANEAMIENTO!A:A,PLANEAMIENTO!D:D) -> 844H | E17: Corte de vastago | F17: Luis Ramos | G17: 2.5 horas | H17: jue 3/10/24 | I17: vie 4/10/24 | J17: 0
B18: 286024 | C18: =_xlfn.XLOOKUP(B18,PLANEAMIENTO!A:A,PLANEAMIENTO!C:C) -> CILINDRO DE DIRECCION | D18: =_xlfn.XLOOKUP(B18,PLANEAMIENTO!A:A,PLANEAMIENTO!D:D) -> 930E-4SE | E18: Fabricación de cáncamo de vástago | F18: Luis Ramos | G18: 1 día | H18: vie 4/10/24 | I18: lun 7/10/24 | J18: 0
B19: OT | C19: DESCRIPCION | D19: MODELO | E19: SOLDADURA 1 | G19: 5.79 días? | H19: lun 30/09/24 | I19: mar 8/10/24 | J19: 0.47
B20: 286624 | C20: =_xlfn.XLOOKUP(B20,PLANEAMIENTO!A:A,PLANEAMIENTO!C:C) -> CILINDRO DE INCLINACION DE BULLDOZER | D20: =_xlfn.XLOOKUP(B20,PLANEAMIENTO!A:A,PLANEAMIENTO!D:D) -> D11T | E20: Soldadura de cilindro | F20: Justo Arocutipa | G20: 11 horas | H20: mié 2/10/24 | I20: jue 3/10/24 | J20: 0.3
B21: 287324 | C21: =_xlfn.XLOOKUP(B21,PLANEAMIENTO!A:A,PLANEAMIENTO!C:C) -> CILINDRO DE DIRECCION | D21: =_xlfn.XLOOKUP(B21,PLANEAMIENTO!A:A,PLANEAMIENTO!D:D) -> 24 | E21: Soldadura de cilindro y relleno de ojo | F21: Justo Arocutipa | G21: 5 horas | H21: vie 4/10/24 | I21: vie 4/10/24 | J21: 0
B22: 287724 | C22: =_xlfn.XLOOKUP(B22,PLANEAMIENTO!A:A,PLANEAMIENTO!C:C) -> CILINDRO DE JACK HYD | D22: =_xlfn.XLOOKUP(B22,PLANEAMIENTO!A:A,PLANEAMIENTO!D:D) -> PITVIPER 351 | E22: Rellenado de tapa posterior cilindro | F22: Justo Arocutipa | G22: 4 horas | H22: vie 4/10/24 | I22: vie 4/10/24 | J22: 0
B23: 273924 | C23: =_xlfn.XLOOKUP(B23,PLANEAMIENTO!A:A,PLANEAMIENTO!C:C) -> CILINDRO DE SUSPENSION POSTERIOR | D23: =_xlfn.XLOOKUP(B23,PLANEAMIENTO!A:A,PLANEAMIENTO!D:D) -> 797F | E23: Soldadura encastre de cilindro | F23: Justo Arocutipa | G23: 7 horas | H23: lun 7/10/24 | I23: lun 7/10/24 | J23: 0
B24: 273924 | C24: =_xlfn.XLOOKUP(B24,PLANEAMIENTO!A:A,PLANEAMIENTO!C:C) -> CILINDRO DE SUSPENSION POSTERIOR | D24: =_xlfn.XLOOKUP(B24,PLANEAMIENTO!A:A,PLANEAMIENTO!D:D) -> 797F | E24: Relleno Ojo de cilindro | F24: Justo Arocutipa | G24: 3 horas | H24: lun 7/10/24 | I24: mar 8/10/24 | J24: 0
B25: OT | C25: DESCRIPCION | D25: MODELO | E25: SOLDADURA 2 | G25: 5.58 días? | H25: lun 30/09/24 | I25: lun 7/10/24 | J25: 0
B26: 287024 | C26: =_xlfn.XLOOKUP(B26,PLANEAMIENTO!A:A,PLANEAMIENTO!C:C) -> CILINDRO DE LEVANTE DE BULLDOZER | D26: =_xlfn.XLOOKUP(B26,PLANEAMIENTO!A:A,PLANEAMIENTO!D:D) -> D475 | E26: Soldadura de encastre de vástago | F26: Victor Caceres | G26: 5 horas | H26: jue 3/10/24 | I26: jue 3/10/24 | J26: 0
B27: 287024 | C27: =_xlfn.XLOOKUP(B27,PLANEAMIENTO!A:A,PLANEAMIENTO!C:C) -> CILINDRO DE LEVANTE DE BULLDOZER | D27: =_xlfn.XLOOKUP(B27,PLANEAMIENTO!A:A,PLANEAMIENTO!D:D) -> D475 | E27: Relleno de ojo de vástago | F27: Victor Caceres | G27: 1 hora | H27: jue 3/10/24 | I27: jue 3/10/24 | J27: 0
B28: 279624 | C28: =_xlfn.XLOOKUP(B28,PLANEAMIENTO!A:A,PLANEAMIENTO!C:C) -> CILINDRO DE SUSPENSION POSTERIOR | D28: =_xlfn.XLOOKUP(B28,PLANEAMIENTO!A:A,PLANEAMIENTO!D:D) -> 797F | E28: Extraer rótula | F28: Victor Caceres | G28: 1 hora | H28: jue 3/10/24 | I28: jue 3/10/24 | J28: 0
B29: 279624 | C29: =_xlfn.XLOOKUP(B29,PLANEAMIENTO!A:A,PLANEAMIENTO!C:C) -> CILINDRO DE SUSPENSION POSTERIOR | D29: =_xlfn.XLOOKUP(B29,PLANEAMIENTO!A:A,PLANEAMIENTO!D:D) -> 797F | E29: Relleno ojo vástago | F29: Victor Caceres | G29: 4 horas | H29: jue 3/10/24 | I29: vie 4/10/24 | J29: 0
B30: 287924 | C30: =_xlfn.XLOOKUP(B30,PLANEAMIENTO!A:A,PLANEAMIENTO!C:C) -> CILINDRO DE STICK | D30: =_xlfn.XLOOKUP(B30,PLANEAMIENTO!A:A,PLANEAMIENTO!D:D) -> 390DL | E30: Extraer cojinete de cilindro | F30: Victor Caceres | G30: 1.3 horas | H30: vie 4/10/24 | I30: vie 4/10/24 | J30: 0
B31: 287924 | C31: =_xlfn.XLOOKUP(B31,PLANEAMIENTO!A:A,PLANEAMIENTO!C:C) -> CILINDRO DE STICK | D31: =_xlfn.XLOOKUP(B31,PLANEAMIENTO!A:A,PLANEAMIENTO!D:D) -> 390DL | E31: Relleno ojo cilindro | F31: Victor Caceres | G31: 6.5 horas | H31: vie 4/10/24 | I31: lun 7/10/24 | J31: 0
B32: OT | C32: DESCRIPCION | D32: MODELO | E32: BRUÑIDO | F32: Gabriel Gallegos | G32: 3.95 días | H32: mar 1/10/24 | I32: lun 7/10/24 | J32: 0.22
B33: 287024 | C33: =_xlfn.XLOOKUP(B33,PLANEAMIENTO!A:A,PLANEAMIENTO!C:C) -> CILINDRO DE LEVANTE DE BULLDOZER | D33: =_xlfn.XLOOKUP(B33,PLANEAMIENTO!A:A,PLANEAMIENTO!D:D) -> D475 | E33: Bruñido | F33: Gabriel Gallegos | G33: 2.5 horas | H33: jue 3/10/24 | I33: jue 3/10/24 | J33: 0.4
B34: 288624 | C34: =_xlfn.XLOOKUP(B34,PLANEAMIENTO!A:A,PLANEAMIENTO!C:C) -> CILINDRO DE BOOM | D34: =_xlfn.XLOOKUP(B34,PLANEAMIENTO!A:A,PLANEAMIENTO!D:D) -> 390DL | E34: Bruñido | F34: Gabriel Gallegos | G34: 2.5 horas | H34: jue 3/10/24 | I34: jue 3/10/24 | J34: 0
B35: 285224 | C35: =_xlfn.XLOOKUP(B35,PLANEAMIENTO!A:A,PLANEAMIENTO!C:C) -> CILINDRO DE INCLINACION DE BULLDOZER | D35: =_xlfn.XLOOKUP(B35,PLANEAMIENTO!A:A,PLANEAMIENTO!D:D) -> D11T | E35: Bruñido | F35: Gabriel Gallegos | G35: 2.5 horas | H35: jue 3/10/24 | I35: jue 3/10/24 | J35: 0
B36: 290724 | C36: =_xlfn.XLOOKUP(B36,PLANEAMIENTO!A:A,PLANEAMIENTO!C:C) -> CILINDRO DE DIRECCION | D36: =_xlfn.XLOOKUP(B36,PLANEAMIENTO!A:A,PLANEAMIENTO!D:D) -> 834K | E36: Bruñido | F36: Gabriel Gallegos | G36: 2.5 horas | H36: vie 4/10/24 | I36: vie 4/10/24 | J36: 0
B37: 290824 | C37: =_xlfn.XLOOKUP(B37,PLANEAMIENTO!A:A,PLANEAMIENTO!C:C) -> CILINDRO DE DIRECCION | D37: =_xlfn.XLOOKUP(B37,PLANEAMIENTO!A:A,PLANEAMIENTO!D:D) -> 834K | E37: Bruñido | F37: Gabriel Gallegos | G37: 2.5 horas | H37: vie 4/10/24 | I37: vie 4/10/24 | J37: 0
B38: 290924 | C38: =_xlfn.XLOOKUP(B38,PLANEAMIENTO!A:A,PLANEAMIENTO!C:C) -> CILINDRO DE LEVANTE DE RIPPER | D38: =_xlfn.XLOOKUP(B38,PLANEAMIENTO!A:A,PLANEAMIENTO!D:D) -> D11T | E38: Bruñido | F38: Gabriel Gallegos | G38: 2.5 horas | H38: vie 4/10/24 | I38: vie 4/10/24 | J38: 0
B39: 287724 | C39: =_xlfn.XLOOKUP(B39,PLANEAMIENTO!A:A,PLANEAMIENTO!C:C) -> CILINDRO DE JACK HYD | D39: =_xlfn.XLOOKUP(B39,PLANEAMIENTO!A:A,PLANEAMIENTO!D:D) -> PITVIPER 351 | E39: Bruñido | F39: Gabriel Gallegos | G39: 2.5 horas | H39: vie 4/10/24 | I39: lun 7/10/24 | J39: 0
B40: 286624 | C40: =_xlfn.XLOOKUP(B40,PLANEAMIENTO!A:A,PLANEAMIENTO!C:C) -> CILINDRO DE INCLINACION DE BULLDOZER | D40: =_xlfn.XLOOKUP(B40,PLANEAMIENTO!A:A,PLANEAMIENTO!D:D) -> D11T | E40: Bruñido | F40: Gabriel Gallegos | G40: 2.5 horas | H40: lun 7/10/24 | I40: lun 7/10/24 | J40: 0
B41: OT | C41: DESCRIPCION | D41: MODELO | E41: EVALUACION | G41: 4.68 días? | H41: mar 1/10/24 | I41: mar 8/10/24 | J41: 0
...

Sheet Programacion
F2: CRONOGRAMA DE ACTIVIDADES
E4: PROYECTO | F4: TALLER HPK | I4: FECHA ACTUAL | J4: =TODAY() -> 46045 | N4: FECHA INICIO | Q4: 45555 | V4: FECHA FIN | Y4: 45656
M13: 1 | N13: =M13+1 -> 2 | O13: =N13+1 -> 3 | P13: =O13+1 -> 4 | Q13: =P13+1 -> 5 | R13: =Q13+1 -> 6 | S13: =R13+1 -> 7 | T13: =S13+1 -> 8 | U13: =T13+1 -> 9 | ... SX13: =SW13+1 -> 506
E14: CROMOGRAMA | M14: =TEXT(M16,"MMM") -> Set | N14: =IFERROR(IF(MONTH(N16)=MONTH(M16),"",TEXT(N16,"MMM")),"") | O14: =IFERROR(IF(MONTH(O16)=MONTH(N16),"",TEXT(O16,"MMM")),"") | P14: =IFERROR(IF(MONTH(P16)=MONTH(O16),"",TEXT(P16,"MMM")),"") | Q14: =IFERROR(IF(MONTH(Q16)=MONTH(P16),"",TEXT(Q16,"MMM")),"") | R14: =IFERROR(IF(MONTH(R16)=MONTH(Q16),"",TEXT(R16,"MMM")),"") | S14: =IFERROR(IF(MONTH(S16)=MONTH(R16),"",TEXT(S16,"MMM")),"") | T14: =IFERROR(IF(MONTH(T16)=MONTH(S16),"",TEXT(T16,"MMM")),"") -> Oct | U14: =IFERROR(IF(MONTH(U16)=MONTH(T16),"",TEXT(U16,"MMM")),"") | ... SX14: =IFERROR(IF(MONTH(SX16)=MONTH(SW16),"",TEXT(SX16,"MMM")),"")
M15: =TEXT(M16,"ddd") -> vie | N15: =TEXT(N16,"ddd") -> lun | O15: =TEXT(O16,"ddd") -> mar | P15: =TEXT(P16,"ddd") -> mié | Q15: =TEXT(Q16,"ddd") -> jue | R15: =TEXT(R16,"ddd") -> vie | S15: =TEXT(S16,"ddd") -> lun | T15: =TEXT(T16,"ddd") -> mar | ... SX15: =TEXT(SX16,"ddd")
B16: AREA | C16: OT | E16: ACTIVIDADES | F16: RESPONSABLE | G16: FECHA INI | H16: Nº DÍAS | I16: FECHA FIN | J16: AVANCE | K16: ESTADO | M16: 45555 | N16: 45558 | O16: 45559 | P16: 45560 | Q16: 45561 | R16: 45562 | S16: 45565 | T16: 45566 | U16: 45567 | V16: 45568 | W16: 45569 | X16: 45572 | Y16: 45573 | Z16: 45574 | AA16: 45575 | AB16: 45576 | AC16: 45579 | AD16: 45580 | AE16: 45581 | AF16: 45582 | AG16: 45583 | AH16: 45586 | AI16: 45587 | AJ16: 45588 | AK16: 45589 | AL16: 45590 | AM16: 45593 | AN16: 45594 | AO16: 45595 | AP16: 45596 | AQ16: 45597 | AR16: 45600 | AS16: 45601 | AT16: 45602 | AU16: 45603 | AV16: 45604 | AW16: 45607 | AX16: 45608 | AY16: 45609 | AZ16: 45610 | BA16: 45611 | BB16: 45614 | BC16: 45615 | BD16: 45616 | BE16: 45617 | BF16: 45618 | BG16: 45621 | BH16: 45622 | BI16: 45623 | BJ16: 45624 | BK16: 45625 | BL16: 45628 | BM16: 45629 | BN16: 45630 | BO16: 45631 | BP16: 45632 | BQ16: 45635 | BR16: 45636 | BS16: 45637 | BT16: 45638 | BU16: 45639 | BV16: 45642 | BW16: 45643 | BX16: 45644 | BY16: 45645 | BZ16: 45646 | CA16: 45649 | CB16: 45650 | CC16: 45651 | CD16: 45652 | CE16: 45653 | CF16: 45656
E18: MAQUINADO
B19: TORNO 1 | C19: 273924 | D19: 1 | E19: Maquinado de encastre de cilindro y medida final OD | F19: Gabriel Anco | G19: 45565 | H19: 1 | I19: =(G19+H19)-1 -> 45565 | J19: 1 | K19: Completado | M19: =IF($J19>0%,IF(AND(M$16>=$G19,M$16<$G19+($H19*$J19)),"➤",""),"") | N19: =IF($J19>0%,IF(AND(N$16>=$G19,N$16<$G19+($H19*$J19)),"➤",""),"") | O19: =IF($J19>0%,IF(AND(O$16>=$G19,O$16<$G19+($H19*$J19)),"➤",""),"") | P19: =IF($J19>0%,IF(AND(P$16>=$G19,P$16<$G19+($H19*$J19)),"➤",""),"") | Q19: =IF($J19>0%,IF(AND(Q$16>=$G19,Q$16<$G19+($H19*$J19)),"➤",""),"") | R19: =IF($J19>0%,IF(AND(R$16>=$G19,R$16<$G19+($H19*$J19)),"➤",""),"") | S19: =IF($J19>0%,IF(AND(S$16>=$G19,S$16<$G19+($H19*$J19)),"➤",""),"") -> ➤ | T19: =IF($J19>0%,IF(AND(T$16>=$G19,T$16<$G19+($H19*$J19)),"➤",""),"") | ... SX19: =IF($J19>0%,IF(AND(SX$16>=$G19,SX$16<$G19+($H19*$J19)),"➤",""),"")
C20: 288724 | D20: 1 | E20: Maquinado de espiga | F20: Gabriel Anco | G20: 45566 | H20: 2 | I20: =(G20+H20)-1 -> 45567 | J20: 0.6 | K20: En Proceso | M20: =IF($J20>0%,IF(AND(M$16>=$G20,M$16<$G20+($H20*$J20)),"➤",""),"") | N20: =IF($J20>0%,IF(AND(N$16>=$G20,N$16<$G20+($H20*$J20)),"➤",""),"") | O20: =IF($J20>0%,IF(AND(O$16>=$G20,O$16<$G20+($H20*$J20)),"➤",""),"") | P20: =IF($J20>0%,IF(AND(P$16>=$G20,P$16<$G20+($H20*$J20)),"➤",""),"") | Q20: =IF($J20>0%,IF(AND(Q$16>=$G20,Q$16<$G20+($H20*$J20)),"➤",""),"") | R20: =IF($J20>0%,IF(AND(R$16>=$G20,R$16<$G20+($H20*$J20)),"➤",""),"") | S20: =IF($J20>0%,IF(AND(S$16>=$G20,S$16<$G20+($H20*$J20)),"➤",""),"") | T20: =IF($J20>0%,IF(AND(T$16>=$G20,T$16<$G20+($H20*$J20)),"➤",""),"") -> ➤ | ... SX20: =IF($J20>0%,IF(AND(SX$16>=$G20,SX$16<$G20+($H20*$J20)),"➤",""),"")
C21: 285724 | D21: 1 | E21: Maquinado de soldadura de tapa posterior de cilindro | F21: Gabriel Anco | G21: 45567 | H21: 1 | I21: =(G21+H21)-1 -> 45567 | J21: 0 | K21: Sin Empezar | M21: =IF($J21>0%,IF(AND(M$16>=$G21,M$16<$G21+($H21*$J21)),"➤",""),"") | N21: =IF($J21>0%,IF(AND(N$16>=$G21,N$16<$G21+($H21*$J21)),"➤",""),"") | O21: =IF($J21>0%,IF(AND(O$16>=$G21,O$16<$G21+($H21*$J21)),"➤",""),"") | P21: =IF($J21>0%,IF(AND(P$16>=$G21,P$16<$G21+($H21*$J21)),"➤",""),"") | Q21: =IF($J21>0%,IF(AND(Q$16>=$G21,Q$16<$G21+($H21*$J21)),"➤",""),"") | R21: =IF($J21>0%,IF(AND(R$16>=$G21,R$16<$G21+($H21*$J21)),"➤",""),"") | S21: =IF($J21>0%,IF(AND(S$16>=$G21,S$16<$G21+($H21*$J21)),"➤",""),"") | T21: =IF($J21>0%,IF(AND(T$16>=$G21,T$16<$G21+($H21*$J21)),"➤",""),"") | ... SX21: =IF($J21>0%,IF(AND(SX$16>=$G21,SX$16<$G21+($H21*$J21)),"➤",""),"")
C22: 285724 | D22: 1 | E22: Montaje de cilindro con tapa posterior para soldadura | F22: Gabriel Anco | G22: 45567 | H22: 1 | I22: =(G22+H22)-1 -> 45567 | J22: 0 | K22: Sin Empezar | M22: =IF($J22>0%,IF(AND(M$16>=$G22,M$16<$G22+($H22*$J22)),"➤",""),"") | N22: =IF($J22>0%,IF(AND(N$16>=$G22,N$16<$G22+($H22*$J22)),"➤",""),"") | O22: =IF($J22>0%,IF(AND(O$16>=$G22,O$16<$G22+($H22*$J22)),"➤",""),"") | P22: =IF($J22>0%,IF(AND(P$16>=$G22,P$16<$G22+($H22*$J22)),"➤",""),"") | Q22: =IF($J22>0%,IF(AND(Q$16>=$G22,Q$16<$G22+($H22*$J22)),"➤",""),"") | R22: =IF($J22>0%,IF(AND(R$16>=$G22,R$16<$G22+($H22*$J22)),"➤",""),"") | S22: =IF($J22>0%,IF(AND(S$16>=$G22,S$16<$G22+($H22*$J22)),"➤",""),"") | T22: =IF($J22>0%,IF(AND(T$16>=$G22,T$16<$G22+($H22*$J22)),"➤",""),"") | ... SX22: =IF($J22>0%,IF(AND(SX$16>=$G22,SX$16<$G22+($H22*$J22)),"➤",""),"")
C23: 286624 | D23: 1 | E23: Maquinado de barra cromada | F23: Gabriel Anco | G23: 45568 | H23: 1 | I23: =(G23+H23)-1 -> 45568 | J23: 0 | K23: Sin Empezar | M23: =IF($J23>0%,IF(AND(M$16>=$G23,M$16<$G23+($H23*$J23)),"➤",""),"") | N23: =IF($J23>0%,IF(AND(N$16>=$G23,N$16<$G23+($H23*$J23)),"➤",""),"") | O23: =IF($J23>0%,IF(AND(O$16>=$G23,O$16<$G23+($H23*$J23)),"➤",""),"") | P23: =IF($J23>0%,IF(AND(P$16>=$G23,P$16<$G23+($H23*$J23)),"➤",""),"") | Q23: =IF($J23>0%,IF(AND(Q$16>=$G23,Q$16<$G23+($H23*$J23)),"➤",""),"") | R23: =IF($J23>0%,IF(AND(R$16>=$G23,R$16<$G23+($H23*$J23)),"➤",""),"") | S23: =IF($J23>0%,IF(AND(S$16>=$G23,S$16<$G23+($H23*$J23)),"➤",""),"") | T23: =IF($J23>0%,IF(AND(T$16>=$G23,T$16<$G23+($H23*$J23)),"➤",""),"") | ... SX23: =IF($J23>0%,IF(AND(SX$16>=$G23,SX$16<$G23+($H23*$J23)),"➤",""),"")
C24: 289224 | E24: Fabricar planchas escalonadas | F24: Gabriel Anco | G24: 45568 | H24: 1 | I24: =(G24+H24)-1 -> 45568 | J24: 0 | K24: Sin Empezar | M24: =IF($J24>0%,IF(AND(M$16>=$G24,M$16<$G24+($H24*$J24)),"➤",""),"") | N24: =IF($J24>0%,IF(AND(N$16>=$G24,N$16<$G24+($H24*$J24)),"➤",""),"") | O24: =IF($J24>0%,IF(AND(O$16>=$G24,O$16<$G24+($H24*$J24)),"➤",""),"") | P24: =IF($J24>0%,IF(AND(P$16>=$G24,P$16<$G24+($H24*$J24)),"➤",""),"") | Q24: =IF($J24>0%,IF(AND(Q$16>=$G24,Q$16<$G24+($H24*$J24)),"➤",""),"") | R24: =IF($J24>0%,IF(AND(R$16>=$G24,R$16<$G24+($H24*$J24)),"➤",""),"") | S24: =IF($J24>0%,IF(AND(S$16>=$G24,S$16<$G24+($H24*$J24)),"➤",""),"") | T24: =IF($J24>0%,IF(AND(T$16>=$G24,T$16<$G24+($H24*$J24)),"➤",""),"") | ... SX24: =IF($J24>0%,IF(AND(SX$16>=$G24,SX$16<$G24+($H24*$J24)),"➤",""),"")
B25: TORNO 2 | C25: 286624 | E25: Corte de cilindro | F25: Rolando Yaique | G25: 45565 | H25: 1 | I25: =(G25+H25)-1 -> 45565 | J25: 1 | K25: Completado | M25: =IF($J25>0%,IF(AND(M$16>=$G25,M$16<$G25+($H25*$J25)),"➤",""),"") | N25: =IF($J25>0%,IF(AND(N$16>=$G25,N$16<$G25+($H25*$J25)),"➤",""),"") | O25: =IF($J25>0%,IF(AND(O$16>=$G25,O$16<$G25+($H25*$J25)),"➤",""),"") | P25: =IF($J25>0%,IF(AND(P$16>=$G25,P$16<$G25+($H25*$J25)),"➤",""),"") | Q25: =IF($J25>0%,IF(AND(Q$16>=$G25,Q$16<$G25+($H25*$J25)),"➤",""),"") | R25: =IF($J25>0%,IF(AND(R$16>=$G25,R$16<$G25+($H25*$J25)),"➤",""),"") | S25: =IF($J25>0%,IF(AND(S$16>=$G25,S$16<$G25+($H25*$J25)),"➤",""),"") -> ➤ | T25: =IF($J25>0%,IF(AND(T$16>=$G25,T$16<$G25+($H25*$J25)),"➤",""),"") | ... SX25: =IF($J25>0%,IF(AND(SX$16>=$G25,SX$16<$G25+($H25*$J25)),"➤",""),"")
C26: 284724 | E26: Rectificado de diámetro de salida | F26: Rolando Yaique | G26: 45565 | H26: 1 | I26: =(G26+H26)-1 -> 45565 | J26: 1 | K26: Completado | M26: =IF($J26>0%,IF(AND(M$16>=$G26,M$16<$G26+($H26*$J26)),"➤",""),"") | N26: =IF($J26>0%,IF(AND(N$16>=$G26,N$16<$G26+($H26*$J26)),"➤",""),"") | O26: =IF($J26>0%,IF(AND(O$16>=$G26,O$16<$G26+($H26*$J26)),"➤",""),"") | P26: =IF($J26>0%,IF(AND(P$16>=$G26,P$16<$G26+($H26*$J26)),"➤",""),"") | Q26: =IF($J26>0%,IF(AND(Q$16>=$G26,Q$16<$G26+($H26*$J26)),"➤",""),"") | R26: =IF($J26>0%,IF(AND(R$16>=$G26,R$16<$G26+($H26*$J26)),"➤",""),"") | S26: =IF($J26>0%,IF(AND(S$16>=$G26,S$16<$G26+($H26*$J26)),"➤",""),"") -> ➤ | T26: =IF($J26>0%,IF(AND(T$16>=$G26,T$16<$G26+($H26*$J26)),"➤",""),"") | ... SX26: =IF($J26>0%,IF(AND(SX$16>=$G26,SX$16<$G26+($H26*$J26)),"➤",""),"")
C27: 286624 | E27: Maquinado de encastre de cilindro y medida final OD | F27: Rolando Yaique | G27: 45566 | H27: 2 | I27: =(G27+H27)-1 -> 45567 | J27: 1 | K27: Completado | M27: =IF($J27>0%,IF(AND(M$16>=$G27,M$16<$G27+($H27*$J27)),"➤",""),"") | N27: =IF($J27>0%,IF(AND(N$16>=$G27,N$16<$G27+($H27*$J27)),"➤",""),"") | O27: =IF($J27>0%,IF(AND(O$16>=$G27,O$16<$G27+($H27*$J27)),"➤",""),"") | P27: =IF($J27>0%,IF(AND(P$16>=$G27,P$16<$G27+($H27*$J27)),"➤",""),"") | Q27: =IF($J27>0%,IF(AND(Q$16>=$G27,Q$16<$G27+($H27*$J27)),"➤",""),"") | R27: =IF($J27>0%,IF(AND(R$16>=$G27,R$16<$G27+($H27*$J27)),"➤",""),"") | S27: =IF($J27>0%,IF(AND(S$16>=$G27,S$16<$G27+($H27*$J27)),"➤",""),"") | T27: =IF($J27>0%,IF(AND(T$16>=$G27,T$16<$G27+($H27*$J27)),"➤",""),"") -> ➤ | ... SX27: =IF($J27>0%,IF(AND(SX$16>=$G27,SX$16<$G27+($H27*$J27)),"➤",""),"")
C28: 288024 | E28: Fabricacion de cojinete | F28: Rolando Yaique | G28: 45566 | H28: 2 | I28: =(G28+H28)-1 -> 45567 | J28: 0 | K28: En Proceso | M28: =IF($J28>0%,IF(AND(M$16>=$G28,M$16<$G28+($H28*$J28)),"➤",""),"") | N28: =IF($J28>0%,IF(AND(N$16>=$G28,N$16<$G28+($H28*$J28)),"➤",""),"") | O28: =IF($J28>0%,IF(AND(O$16>=$G28,O$16<$G28+($H28*$J28)),"➤",""),"") | P28: =IF($J28>0%,IF(AND(P$16>=$G28,P$16<$G28+($H28*$J28)),"➤",""),"") | Q28: =IF($J28>0%,IF(AND(Q$16>=$G28,Q$16<$G28+($H28*$J28)),"➤",""),"") | R28: =IF($J28>0%,IF(AND(R$16>=$G28,R$16<$G28+($H28*$J28)),"➤",""),"") | S28: =IF($J28>0%,IF(AND(S$16>=$G28,S$16<$G28+($H28*$J28)),"➤",""),"") | T28: =IF($J28>0%,IF(AND(T$16>=$G28,T$16<$G28+($H28*$J28)),"➤",""),"") | ... SX28: =IF($J28>0%,IF(AND(SX$16>=$G28,SX$16<$G28+($H28*$J28)),"➤",""),"")
C29: 288324 | E29: Corte cilindro | F29: Rolando Yaique | G29: 45567 | H29: 1 | I29: =(G29+H29)-1 -> 45567 | J29: 0 | K29: Sin Empezar | M29: =IF($J29>0%,IF(AND(M$16>=$G29,M$16<$G29+($H29*$J29)),"➤",""),"") | N29: =IF($J29>0%,IF(AND(N$16>=$G29,N$16<$G29+($H29*$J29)),"➤",""),"") | O29: =IF($J29>0%,IF(AND(O$16>=$G29,O$16<$G29+($H29*$J29)),"➤",""),"") | P29: =IF($J29>0%,IF(AND(P$16>=$G29,P$16<$G29+($H29*$J29)),"➤",""),"") | Q29: =IF($J29>0%,IF(AND(Q$16>=$G29,Q$16<$G29+($H29*$J29)),"➤",""),"") | R29: =IF($J29>0%,IF(AND(R$16>=$G29,R$16<$G29+($H29*$J29)),"➤",""),"") | S29: =IF($J29>0%,IF(AND(S$16>=$G29,S$16<$G29+($H29*$J29)),"➤",""),"") | T29: =IF($J29>0%,IF(AND(T$16>=$G29,T$16<$G29+($H29*$J29)),"➤",""),"") | ... SX29: =IF($J29>0%,IF(AND(SX$16>=$G29,SX$16<$G29+($H29*$J29)),"➤",""),"")
C30: 288324 | E30: Maquinado de encastre | F30: Rolando Yaique | G30: 45568 | H30: 1 | I30: =(G30+H30)-1 -> 45568 | J30: 0 | K30: Sin Empezar | M30: =IF($J30>0%,IF(AND(M$16>=$G30,M$16<$G30+($H30*$J30)),"➤",""),"") | N30: =IF($J30>0%,IF(AND(N$16>=$G30,N$16<$G30+($H30*$J30)),"➤",""),"") | O30: =IF($J30>0%,IF(AND(O$16>=$G30,O$16<$G30+($H30*$J30)),"➤",""),"") | P30: =IF($J30>0%,IF(AND(P$16>=$G30,P$16<$G30+($H30*$J30)),"➤",""),"") | Q30: =IF($J30>0%,IF(AND(Q$16>=$G30,Q$16<$G30+($H30*$J30)),"➤",""),"") | R30: =IF($J30>0%,IF(AND(R$16>=$G30,R$16<$G30+($H30*$J30)),"➤",""),"") | S30: =IF($J30>0%,IF(AND(S$16>=$G30,S$16<$G30+($H30*$J30)),"➤",""),"") | T30: =IF($J30>0%,IF(AND(T$16>=$G30,T$16<$G30+($H30*$J30)),"➤",""),"") | ... SX30: =IF($J30>0%,IF(AND(SX$16>=$G30,SX$16<$G30+($H30*$J30)),"➤",""),"")
M32: =IF($J32>0%,IF(AND(M$16>=$G32,M$16<$G32+($H32*$J32)),"➤",""),"") | N32: =IF($J32>0%,IF(AND(N$16>=$G32,N$16<$G32+($H32*$J32)),"➤",""),"") | O32: =IF($J32>0%,IF(AND(O$16>=$G32,O$16<$G32+($H32*$J32)),"➤",""),"") | P32: =IF($J32>0%,IF(AND(P$16>=$G32,P$16<$G32+($H32*$J32)),"➤",""),"") | Q32: =IF($J32>0%,IF(AND(Q$16>=$G32,Q$16<$G32+($H32*$J32)),"➤",""),"") | R32: =IF($J32>0%,IF(AND(R$16>=$G32,R$16<$G32+($H32*$J32)),"➤",""),"") | S32: =IF($J32>0%,IF(AND(S$16>=$G32,S$16<$G32+($H32*$J32)),"➤",""),"") | T32: =IF($J32>0%,IF(AND(T$16>=$G32,T$16<$G32+($H32*$J32)),"➤",""),"") | ... SX32: =IF($J32>0%,IF(AND(SX$16>=$G32,SX$16<$G32+($H32*$J32)),"➤",""),"")
B33: TORNO 3 | C33: 287024 | E33: Corte de barra - cancamo | F33: Luis Ramos | G33: 45565 | H33: 1 | I33: =(G33+H33)-1 -> 45565 | J33: 1 | K33: Completado | M33: =IF($J33>0%,IF(AND(M$16>=$G33,M$16<$G33+($H33*$J33)),"➤",""),"") | N33: =IF($J33>0%,IF(AND(N$16>=$G33,N$16<$G33+($H33*$J33)),"➤",""),"") | O33: =IF($J33>0%,IF(AND(O$16>=$G33,O$16<$G33+($H33*$J33)),"➤",""),"") | P33: =IF($J33>0%,IF(AND(P$16>=$G33,P$16<$G33+($H33*$J33)),"➤",""),"") | Q33: =IF($J33>0%,IF(AND(Q$16>=$G33,Q$16<$G33+($H33*$J33)),"➤",""),"") | R33: =IF($J33>0%,IF(AND(R$16>=$G33,R$16<$G33+($H33*$J33)),"➤",""),"") | S33: =IF($J33>0%,IF(AND(S$16>=$G33,S$16<$G33+($H33*$J33)),"➤",""),"") -> ➤ | T33: =IF($J33>0%,IF(AND(T$16>=$G33,T$16<$G33+($H33*$J33)),"➤",""),"") | ... SX33: =IF($J33>0%,IF(AND(SX$16>=$G33,SX$16<$G33+($H33*$J33)),"➤",""),"")
C34: 287024 | E34: Maquinado de vástago | F34: Luis Ramos | G34: 45565 | H34: 1 | I34: =(G34+H34)-1 -> 45565 | J34: 1 | K34: Completado | M34: =IF($J34>0%,IF(AND(M$16>=$G34,M$16<$G34+($H34*$J34)),"➤",""),"") | N34: =IF($J34>0%,IF(AND(N$16>=$G34,N$16<$G34+($H34*$J34)),"➤",""),"") | O34: =IF($J34>0%,IF(AND(O$16>=$G34,O$16<$G34+($H34*$J34)),"➤",""),"") | P34: =IF($J34>0%,IF(AND(P$16>=$G34,P$16<$G34+($H34*$J34)),"➤",""),"") | Q34: =IF($J34>0%,IF(AND(Q$16>=$G34,Q$16<$G34+($H34*$J34)),"➤",""),"") | R34: =IF($J34>0%,IF(AND(R$16>=$G34,R$16<$G34+($H34*$J34)),"➤",""),"") | S34: =IF($J34>0%,IF(AND(S$16>=$G34,S$16<$G34+($H34*$J34)),"➤",""),"") -> ➤ | T34: =IF($J34>0%,IF(AND(T$16>=$G34,T$16<$G34+($H34*$J34)),"➤",""),"") | ... AF34: =IF($J34>0%,IF(AND(AF$16>=$G34,AF$16<$G34+($H34*$J34)),"➤",""),"") | AG34: =IF($J34>0%,IF(AND(AG$16>=$G37,AG$16<$G37+($H34*$J34)),"➤",""),"") | AH34: =IF($J34>0%,IF(AND(AH$16>=$G37,AH$16<$G37+($H34*$J34)),"➤",""),"") | AI34: =IF($J34>0%,IF(AND(AI$16>=$G37,AI$16<$G37+($H34*$J34)),"➤",""),"") | AJ34: =IF($J34>0%,IF(AND(AJ$16>=$G37,AJ$16<$G37+($H34*$J34)),"➤",""),"") | AK34: =IF($J34>0%,IF(AND(AK$16>=$G37,AK$16<$G37+($H34*$J34)),"➤",""),"") | AL34: =IF($J34>0%,IF(AND(AL$16>=$G37,AL$16<$G37+($H34*$J34)),"➤",""),"") | AM34: =IF($J34>0%,IF(AND(AM$16>=$G37,AM$16<$G37+($H34*$J34)),"➤",""),"") | AN34: =IF($J34>0%,IF(AND(AN$16>=$G37,AN$16<$G37+($H34*$J34)),"➤",""),"") | ... SX34: =IF($J34>0%,IF(AND(SX$16>=$G37,SX$16<$G37+($H34*$J34)),"➤",""),"")
C35: 285324 | E35: Maquinado de rosca de tapa | F35: Luis Ramos | G35: 45566 | H35: 1 | I35: =(G35+H35)-1 -> 45566 | J35: 1 | K35: Completado | M35: =IF($J35>0%,IF(AND(M$16>=$G35,M$16<$G35+($H35*$J35)),"➤",""),"") | N35: =IF($J35>0%,IF(AND(N$16>=$G35,N$16<$G35+($H35*$J35)),"➤",""),"") | O35: =IF($J35>0%,IF(AND(O$16>=$G35,O$16<$G35+($H35*$J35)),"➤",""),"") | P35: =IF($J35>0%,IF(AND(P$16>=$G35,P$16<$G35+($H35*$J35)),"➤",""),"") | Q35: =IF($J35>0%,IF(AND(Q$16>=$G35,Q$16<$G35+($H35*$J35)),"➤",""),"") | R35: =IF($J35>0%,IF(AND(R$16>=$G35,R$16<$G35+($H35*$J35)),"➤",""),"") | S35: =IF($J35>0%,IF(AND(S$16>=$G35,S$16<$G35+($H35*$J35)),"➤",""),"") | T35: =IF($J35>0%,IF(AND(T$16>=$G35,T$16<$G35+($H35*$J35)),"➤",""),"") -> ➤ | ... AF35: =IF($J35>0%,IF(AND(AF$16>=$G35,AF$16<$G35+($H35*$J35)),"➤",""),"") | AG35: =IF($J35>0%,IF(AND(AG$16>=$G39,AG$16<$G39+($H35*$J35)),"➤",""),"") | AH35: =IF($J35>0%,IF(AND(AH$16>=$G39,AH$16<$G39+($H35*$J35)),"➤",""),"") | AI35: =IF($J35>0%,IF(AND(AI$16>=$G39,AI$16<$G39+($H35*$J35)),"➤",""),"") | AJ35: =IF($J35>0%,IF(AND(AJ$16>=$G39,AJ$16<$G39+($H35*$J35)),"➤",""),"") | AK35: =IF($J35>0%,IF(AND(AK$16>=$G39,AK$16<$G39+($H35*$J35)),"➤",""),"") | AL35: =IF($J35>0%,IF(AND(AL$16>=$G39,AL$16<$G39+($H35*$J35)),"➤",""),"") | AM35: =IF($J35>0%,IF(AND(AM$16>=$G39,AM$16<$G39+($H35*$J35)),"➤",""),"") | AN35: =IF($J35>0%,IF(AND(AN$16>=$G39,AN$16<$G39+($H35*$J35)),"➤",""),"") | ... SX35: =IF($J35>0%,IF(AND(SX$16>=$G39,SX$16<$G39+($H35*$J35)),"➤",""),"")
C36: 288024 | E36: Maquinado de bocinas | F36: Luis Ramos | G36: 45566 | H36: 2 | I36: =(G36+H36)-1 -> 45567 | J36: 0.25 | K36: En Proceso | M36: =IF($J36>0%,IF(AND(M$16>=$G39,M$16<$G39+($H36*$J36)),"➤",""),"") | N36: =IF($J36>0%,IF(AND(N$16>=$G39,N$16<$G39+($H36*$J36)),"➤",""),"") | O36: =IF($J36>0%,IF(AND(O$16>=$G39,O$16<$G39+($H36*$J36)),"➤",""),"") | P36: =IF($J36>0%,IF(AND(P$16>=$G39,P$16<$G39+($H36*$J36)),"➤",""),"") | Q36: =IF($J36>0%,IF(AND(Q$16>=$G39,Q$16<$G39+($H36*$J36)),"➤",""),"") | R36: =IF($J36>0%,IF(AND(R$16>=$G39,R$16<$G39+($H36*$J36)),"➤",""),"") | S36: =IF($J36>0%,IF(AND(S$16>=$G36,S$16<$G36+($H36*$J36)),"➤",""),"") | T36: =IF($J36>0%,IF(AND(T$16>=$G36,T$16<$G36+($H36*$J36)),"➤",""),"") -> ➤ | U36: =IF($J36>0%,IF(AND(U$16>=$G36,U$16<$G36+($H36*$J36)),"➤",""),"") | V36: =IF($J36>0%,IF(AND(V$16>=$G36,V$16<$G36+($H36*$J36)),"➤",""),"") | W36: =IF($J36>0%,IF(AND(W$16>=$G36,W$16<$G36+($H36*$J36)),"➤",""),"") | X36: =IF($J36>0%,IF(AND(X$16>=$G36,X$16<$G36+($H36*$J36)),"➤",""),"") | Y36: =IF($J36>0%,IF(AND(Y$16>=$G36,Y$16<$G36+($H36*$J36)),"➤",""),"") | Z36: =IF($J36>0%,IF(AND(Z$16>=$G36,Z$16<$G36+($H36*$J36)),"➤",""),"") | ... AF36: =IF($J36>0%,IF(AND(AF$16>=$G36,AF$16<$G36+($H36*$J36)),"➤",""),"") | AG36: =IF($J36>0%,IF(AND(AG$16>=$G39,AG$16<$G39+($H36*$J36)),"➤",""),"") | AH36: =IF($J36>0%,IF(AND(AH$16>=$G39,AH$16<$G39+($H36*$J36)),"➤",""),"") | AI36: =IF($J36>0%,IF(AND(AI$16>=$G39,AI$16<$G39+($H36*$J36)),"➤",""),"") | AJ36: =IF($J36>0%,IF(AND(AJ$16>=$G39,AJ$16<$G39+($H36*$J36)),"➤",""),"") | AK36: =IF($J36>0%,IF(AND(AK$16>=$G39,AK$16<$G39+($H36*$J36)),"➤",""),"") | AL36: =IF($J36>0%,IF(AND(AL$16>=$G39,AL$16<$G39+($H36*$J36)),"➤",""),"") | AM36: =IF($J36>0%,IF(AND(AM$16>=$G39,AM$16<$G39+($H36*$J36)),"➤",""),"") | AN36: =IF($J36>0%,IF(AND(AN$16>=$G39,AN$16<$G39+($H36*$J36)),"➤",""),"") | ... SX36: =IF($J36>0%,IF(AND(SX$16>=$G39,SX$16<$G39+($H36*$J36)),"➤",""),"")
C37: 287024 | E37: Maquinado de bocinas | F37: Luis Ramos | G37: 45568 | H37: 2 | I37: =(G37+H37)-1 -> 45569 | J37: 0 | K37: Sin Empezar | M37: =IF($J37>0%,IF(AND(M$16>=$G40,M$16<$G40+($H37*$J37)),"➤",""),"") | N37: =IF($J37>0%,IF(AND(N$16>=$G40,N$16<$G40+($H37*$J37)),"➤",""),"") | O37: =IF($J37>0%,IF(AND(O$16>=$G40,O$16<$G40+($H37*$J37)),"➤",""),"") | P37: =IF($J37>0%,IF(AND(P$16>=$G40,P$16<$G40+($H37*$J37)),"➤",""),"") | Q37: =IF($J37>0%,IF(AND(Q$16>=$G40,Q$16<$G40+($H37*$J37)),"➤",""),"") | R37: =IF($J37>0%,IF(AND(R$16>=$G40,R$16<$G40+($H37*$J37)),"➤",""),"") | S37: =IF($J37>0%,IF(AND(S$16>=$G37,S$16<$G37+($H37*$J37)),"➤",""),"") | T37: =IF($J37>0%,IF(AND(T$16>=$G37,T$16<$G37+($H37*$J37)),"➤",""),"") | U37: =IF($J37>0%,IF(AND(U$16>=$G37,U$16<$G37+($H37*$J37)),"➤",""),"") | V37: =IF($J37>0%,IF(AND(V$16>=$G37,V$16<$G37+($H37*$J37)),"➤",""),"") | W37: =IF($J37>0%,IF(AND(W$16>=$G37,W$16<$G37+($H37*$J37)),"➤",""),"") | X37: =IF($J37>0%,IF(AND(X$16>=$G37,X$16<$G37+($H37*$J37)),"➤",""),"") | Y37: =IF($J37>0%,IF(AND(Y$16>=$G37,Y$16<$G37+($H37*$J37)),"➤",""),"") | Z37: =IF($J37>0%,IF(AND(Z$16>=$G37,Z$16<$G37+($H37*$J37)),"➤",""),"") | ... AF37: =IF($J37>0%,IF(AND(AF$16>=$G37,AF$16<$G37+($H37*$J37)),"➤",""),"") | AG37: =IF($J37>0%,IF(AND(AG$16>=$G40,AG$16<$G40+($H37*$J37)),"➤",""),"") | AH37: =IF($J37>0%,IF(AND(AH$16>=$G40,AH$16<$G40+($H37*$J37)),"➤",""),"") | AI37: =IF($J37>0%,IF(AND(AI$16>=$G40,AI$16<$G40+($H37*$J37)),"➤",""),"") | AJ37: =IF($J37>0%,IF(AND(AJ$16>=$G40,AJ$16<$G40+($H37*$J37)),"➤",""),"") | AK37: =IF($J37>0%,IF(AND(AK$16>=$G40,AK$16<$G40+($H37*$J37)),"➤",""),"") | AL37: =IF($J37>0%,IF(AND(AL$16>=$G40,AL$16<$G40+($H37*$J37)),"➤",""),"") | AM37: =IF($J37>0%,IF(AND(AM$16>=$G40,AM$16<$G40+($H37*$J37)),"➤",""),"") | AN37: =IF($J37>0%,IF(AND(AN$16>=$G40,AN$16<$G40+($H37*$J37)),"➤",""),"") | ... SX37: =IF($J37>0%,IF(AND(SX$16>=$G40,SX$16<$G40+($H37*$J37)),"➤",""),"")
C38: 287324 | E38: Corte de cilindro | F38: Luis Ramos | G38: 45569 | H38: 1 | I38: =(G38+H38)-1 -> 45569 | J38: 0 | K38: Sin Empezar | M38: =IF($J38>0%,IF(AND(M$16>=$G38,M$16<$G38+($H38*$J38)),"➤",""),"") | N38: =IF($J38>0%,IF(AND(N$16>=$G38,N$16<$G38+($H38*$J38)),"➤",""),"") | O38: =IF($J38>0%,IF(AND(O$16>=$G38,O$16<$G38+($H38*$J38)),"➤",""),"") | P38: =IF($J38>0%,IF(AND(P$16>=$G38,P$16<$G38+($H38*$J38)),"➤",""),"") | Q38: =IF($J38>0%,IF(AND(Q$16>=$G38,Q$16<$G38+($H38*$J38)),"➤",""),"") | R38: =IF($J38>0%,IF(AND(R$16>=$G38,R$16<$G38+($H38*$J38)),"➤",""),"") | S38: =IF($J38>0%,IF(AND(S$16>=$G38,S$16<$G38+($H38*$J38)),"➤",""),"") | T38: =IF($J38>0%,IF(AND(T$16>=$G38,T$16<$G38+($H38*$J38)),"➤",""),"") | ... SX38: =IF($J38>0%,IF(AND(SX$16>=$G38,SX$16<$G38+($H38*$J38)),"➤",""),"")
C39: 287324 | E39: Maquinado de encastre de cilindro y medida final OD | F39: Luis Ramos | G39: 45569 | H39: 1 | I39: =(G39+H39)-1 -> 45569 | J39: 0 | K39: Sin Empezar | M39: =IF($J39>0%,IF(AND(M$16>=$G39,M$16<$G39+($H39*$J39)),"➤",""),"") | N39: =IF($J39>0%,IF(AND(N$16>=$G39,N$16<$G39+($H39*$J39)),"➤",""),"") | O39: =IF($J39>0%,IF(AND(O$16>=$G39,O$16<$G39+($H39*$J39)),"➤",""),"") | P39: =IF($J39>0%,IF(AND(P$16>=$G39,P$16<$G39+($H39*$J39)),"➤",""),"") | Q39: =IF($J39>0%,IF(AND(Q$16>=$G39,Q$16<$G39+($H39*$J39)),"➤",""),"") | R39: =IF($J39>0%,IF(AND(R$16>=$G39,R$16<$G39+($H39*$J39)),"➤",""),"") | S39: =IF($J39>0%,IF(AND(S$16>=$G39,S$16<$G39+($H39*$J39)),"➤",""),"") | T39: =IF($J39>0%,IF(AND(T$16>=$G39,T$16<$G39+($H39*$J39)),"➤",""),"") | ... SX39: =IF($J39>0%,IF(AND(SX$16>=$G39,SX$16<$G39+($H39*$J39)),"➤",""),"")
C40: 286024 | E40: Revisar acero para maquinado de cáncamo | F40: Luis Ramos | H40: 1 | I40: =(G40+H40)-1 -> 0 | J40: 0 | K40: Sin Empezar | M40: =IF($J40>0%,IF(AND(M$16>=$G41,M$16<$G41+($H40*$J40)),"➤",""),"") | N40: =IF($J40>0%,IF(AND(N$16>=$G41,N$16<$G41+($H40*$J40)),"➤",""),"") | O40: =IF($J40>0%,IF(AND(O$16>=$G41,O$16<$G41+($H40*$J40)),"➤",""),"") | P40: =IF($J40>0%,IF(AND(P$16>=$G41,P$16<$G41+($H40*$J40)),"➤",""),"") | Q40: =IF($J40>0%,IF(AND(Q$16>=$G41,Q$16<$G41+($H40*$J40)),"➤",""),"") | R40: =IF($J40>0%,IF(AND(R$16>=$G41,R$16<$G41+($H40*$J40)),"➤",""),"") | S40: =IF($J40>0%,IF(AND(S$16>=$G40,S$16<$G40+($H40*$J40)),"➤",""),"") | T40: =IF($J40>0%,IF(AND(T$16>=$G40,T$16<$G40+($H40*$J40)),"➤",""),"") | U40: =IF($J40>0%,IF(AND(U$16>=$G40,U$16<$G40+($H40*$J40)),"➤",""),"") | V40: =IF($J40>0%,IF(AND(V$16>=$G40,V$16<$G40+($H40*$J40)),"➤",""),"") | W40: =IF($J40>0%,IF(AND(W$16>=$G40,W$16<$G40+($H40*$J40)),"➤",""),"") | X40: =IF($J40>0%,IF(AND(X$16>=$G40,X$16<$G40+($H40*$J40)),"➤",""),"") | Y40: =IF($J40>0%,IF(AND(Y$16>=$G40,Y$16<$G40+($H40*$J40)),"➤",""),"") | Z40: =IF($J40>0%,IF(AND(Z$16>=$G40,Z$16<$G40+($H40*$J40)),"➤",""),"") | ... AF40: =IF($J40>0%,IF(AND(AF$16>=$G40,AF$16<$G40+($H40*$J40)),"➤",""),"") | AG40: =IF($J40>0%,IF(AND(AG$16>=$G41,AG$16<$G41+($H40*$J40)),"➤",""),"") | AH40: =IF($J40>0%,IF(AND(AH$16>=$G41,AH$16<$G41+($H40*$J40)),"➤",""),"") | AI40: =IF($J40>0%,IF(AND(AI$16>=$G41,AI$16<$G41+($H40*$J40)),"➤",""),"") | AJ40: =IF($J40>0%,IF(AND(AJ$16>=$G41,AJ$16<$G41+($H40*$J40)),"➤",""),"") | AK40: =IF($J40>0%,IF(AND(AK$16>=$G41,AK$16<$G41+($H40*$J40)),"➤",""),"") | AL40: =IF($J40>0%,IF(AND(AL$16>=$G41,AL$16<$G41+($H40*$J40)),"➤",""),"") | AM40: =IF($J40>0%,IF(AND(AM$16>=$G41,AM$16<$G41+($H40*$J40)),"➤",""),"") | AN40: =IF($J40>0%,IF(AND(AN$16>=$G41,AN$16<$G41+($H40*$J40)),"➤",""),"") | ... SX40: =IF($J40>0%,IF(AND(SX$16>=$G41,SX$16<$G41+($H40*$J40)),"➤",""),"")
C41: 286024 | E41: Fabricacion de pistón | F41: Luis Ramos | G41: 45572 | H41: 2 | I41: =(G41+H41)-1 -> 45573 | J41: 0 | K41: Sin Empezar | M41: =IF($J41>0%,IF(AND(M$16>=$G42,M$16<$G42+($H41*$J41)),"➤",""),"") | N41: =IF($J41>0%,IF(AND(N$16>=$G42,N$16<$G42+($H41*$J41)),"➤",""),"") | O41: =IF($J41>0%,IF(AND(O$16>=$G42,O$16<$G42+($H41*$J41)),"➤",""),"") | P41: =IF($J41>0%,IF(AND(P$16>=$G42,P$16<$G42+($H41*$J41)),"➤",""),"") | Q41: =IF($J41>0%,IF(AND(Q$16>=$G42,Q$16<$G42+($H41*$J41)),"➤",""),"") | R41: =IF($J41>0%,IF(AND(R$16>=$G42,R$16<$G42+($H41*$J41)),"➤",""),"") | S41: =IF($J41>0%,IF(AND(S$16>=$G41,S$16<$G41+($H41*$J41)),"➤",""),"") | T41: =IF($J41>0%,IF(AND(T$16>=$G41,T$16<$G41+($H41*$J41)),"➤",""),"") | U41: =IF($J41>0%,IF(AND(U$16>=$G41,U$16<$G41+($H41*$J41)),"➤",""),"") | V41: =IF($J41>0%,IF(AND(V$16>=$G41,V$16<$G41+($H41*$J41)),"➤",""),"") | W41: =IF($J41>0%,IF(AND(W$16>=$G41,W$16<$G41+($H41*$J41)),"➤",""),"") | X41: =IF($J41>0%,IF(AND(X$16>=$G41,X$16<$G41+($H41*$J41)),"➤",""),"") | Y41: =IF($J41>0%,IF(AND(Y$16>=$G41,Y$16<$G41+($H41*$J41)),"➤",""),"") | Z41: =IF($J41>0%,IF(AND(Z$16>=$G41,Z$16<$G41+($H41*$J41)),"➤",""),"") | ... AF41: =IF($J41>0%,IF(AND(AF$16>=$G41,AF$16<$G41+($H41*$J41)),"➤",""),"") | AG41: =IF($J41>0%,IF(AND(AG$16>=$G42,AG$16<$G42+($H41*$J41)),"➤",""),"") | AH41: =IF($J41>0%,IF(AND(AH$16>=$G42,AH$16<$G42+($H41*$J41)),"➤",""),"") | AI41: =IF($J41>0%,IF(AND(AI$16>=$G42,AI$16<$G42+($H41*$J41)),"➤",""),"") | AJ41: =IF($J41>0%,IF(AND(AJ$16>=$G42,AJ$16<$G42+($H41*$J41)),"➤",""),"") | AK41: =IF($J41>0%,IF(AND(AK$16>=$G42,AK$16<$G42+($H41*$J41)),"➤",""),"") | AL41: =IF($J41>0%,IF(AND(AL$16>=$G42,AL$16<$G42+($H41*$J41)),"➤",""),"") | AM41: =IF($J41>0%,IF(AND(AM$16>=$G42,AM$16<$G42+($H41*$J41)),"➤",""),"") | AN41: =IF($J41>0%,IF(AND(AN$16>=$G42,AN$16<$G42+($H41*$J41)),"➤",""),"") | ... SX41: =IF($J41>0%,IF(AND(SX$16>=$G42,SX$16<$G42+($H41*$J41)),"➤",""),"")
